Workbook

Sheet Groups
A1: Name | B1: priceCategory | C1: wildnessMultiplier | D1: IsRoamer | E1: filthMultiplier | F1: coldResistance | G1: heatResistance | H1: Integument tensile strength (MPa) | I1: Integument elongation at break (%) | J1: Integument density (kg/L) | K1: Skin mass fraction | L1: IsArmored | M1: IsStrongPuncher | N1: Bite force type | O1: isTeethless | P1: Do leg attack | Q1: Poke/leg claws attack interval | R1: Leg attack linkedBodyPartsGroup | S1: Leg attack label | T1: Leg attack capacities | U1: Horn/Tusk/Misc attack type | V1: Horn/Tusk/Misc attack interval | W1: Horn/Tusk/Misc attack linkedBodyPartsGroup | X1: Horn/Tusk/Misc attack label | Y1: Horn/Tusk/Misc attack capacities | Z1: Bite attack interval | AA1: Bite attack linkedBodyPartsGroup | AB1: Bite attack label | AC1: Bite attack capacities | AD1: Do claw/arm attack | AE1: Claw/arm attack interval | AF1: Claw/arm attack linkedBodyPartsGroup | AG1: Claw/arm attack label | AH1: Claw/arm attack capacities | AI1: HealthMultiplier | AJ1: Physiology | AK1: CanMigrate | AL1: Body | AM1: teethScalinngFormula | AN1: baseManhunterOnTameFailChance | AO1: baseManhunterOnDamageChance | AP1: petnessFactor | AQ1: isVeryFertile | AR1: Trainability | AS1: canHuntLivePrey | AT1: canHuntFish | AU1: isSemiAquatic | AV1: SpecialTradeTags | AW1: NoFlee | AX1: cannotBeAugmented | AY1: cannotBeMutated | AZ1: ScavengerTier | BA1: CannotChew | BB1: TakingCareOfOffspring | BC1: isSluggish | BD1: isBluntHorned | BE1: IsBiped | BF1: biteTeethType | BG1: meleeDodgeChanceMultiplier | BH1: meleeCritChanceMultiplier | BI1: meleeParryChanceMultiplier | BJ1: BodyShape | BK1: ArmorPiercingClaw | BL1: ArmorPiercingHorn | BM1: ArmorPiercingBite
A2: Beetle | B2: 1 | C2: 1.1 | D2: 0 | E2: 1 | F2: 0 | G2: 2 | H2: 95 | I2: =H2/1000/AVERAGE(4.6) -> 0.020652174 | J2: 1.2 | K2: 0.32 | L2: 1 | M2: 1 | N2: Insect | O2: 0 | P2: 0 | Q2: No | R2: No | S2: No | T2: No | U2: No | V2: No | W2: No | X2: No | Y2: No | Z2: 1.2 | AA2: Mouth | AB2: mandibles | AC2: Bite | AD2: 0 | AE2: No | AF2: No | AG2: No | AH2: No | AI2: 1 | AJ2: Invertebrate | AK2: 0 | AL2: BeetleLike | AM2: 0 | AN2: 1 | AO2: 1 | AP2: No | AQ2: 0 | AR2: Advanced | AS2: 1 | AT2: 0 | AU2: 0 | AV2: No | AW2: 0 | AX2: 0 | AY2: 0 | AZ2: 2 | BA2: 0 | BB2: 0 | BC2: 1 | BD2: 0 | BE2: 0 | BF2: 0 | BG2: 0.25 | BH2: 0.1 | BI2: 0.025 | BJ2: QuadrupedLow | BK2: 0 | BL2: 0 | BM2: 0
A3: Beetle (QUEEN) | B3: 1 | C3: 1.1 | D3: 0 | E3: 1 | F3: 0 | G3: 2 | H3: 1400 | I3: =AVERAGE(12.1%,36.3%) -> 0.242 | J3: 0.89 | K3: Unknown | L3: 1 | M3: 1 | N3: Insect | O3: 0 | P3: 0 | Q3: No | R3: No | S3: No | T3: No | U3: No | V3: No | W3: No | X3: No | Y3: No | Z3: 1.2 | AA3: Mouth | AB3: mandibles | AC3: Bite | AD3: 0 | AE3: No | AF3: No | AG3: No | AH3: No | AI3: 1 | AJ3: Invertebrate | AK3: 0 | AL3: BeetleLike | AM3: 0 | AN3: 1 | AO3: 1 | AP3: No | AQ3: 0 | AR3: Advanced | AS3: 1 | AT3: 0 | AU3: 0 | AV3: No | AW3: 0 | AX3: 0 | AY3: 0 | AZ3: 2 | BA3: 0 | BB3: 0 | BC3: 1 | BD3: 0 | BE3: 0 | BF3: 0 | BG3: 0.25 | BH3: 0.1 | BI3: 0.025 | BJ3: QuadrupedLow | BK3: 0 | BL3: 0 | BM3: 0
A4: Beetle (LARVA) | B4: 1 | C4: 1.1 | D4: 0 | E4: 1 | F4: 0 | G4: 2 | H4: 95 | I4: =H4/1000/AVERAGE(4.6) -> 0.020652174 | J4: 1.2 | K4: 0.32 | L4: 1 | M4: 1 | N4: Insect | O4: 0 | P4: 0 | Q4: No | R4: No | S4: No | T4: No | U4: No | V4: No | W4: No | X4: No | Y4: No | Z4: 1.2 | AA4: Mouth | AB4: mandibles | AC4: Bite | AD4: 0 | AE4: No | AF4: No | AG4: No | AH4: No | AI4: 1 | AJ4: Invertebrate | AK4: 0 | AL4: Larva | AM4: 0 | AN4: 1 | AO4: 1 | AP4: No | AQ4: 0 | AR4: Intermediate | AS4: 1 | AT4: 0 | AU4: 0 | AV4: No | AW4: 0 | AX4: 0 | AY4: 0 | AZ4: 2 | BA4: 0 | BB4: 0 | BC4: 1 | BD4: 0 | BE4: 0 | BF4: 0 | BG4: 0.25 | BH4: 0.1 | BI4: 0.025 | BJ4: Serpentine | BK4: 0 | BL4: 0 | BM4: 0
A5: Beetle (CLAWS) | B5: 1 | C5: 1.1 | D5: 0 | E5: 1 | F5: 0 | G5: 2 | H5: 95 | I5: =H5/1000/AVERAGE(4.6) -> 0.020652174 | J5: 1.2 | K5: 0.32 | L5: 1 | M5: 1 | N5: Insect | O5: 0 | P5: 0 | Q5: No | R5: No | S5: No | T5: No | U5: No | V5: No | W5: No | X5: No | Y5: No | Z5: 1.2 | AA5: Mouth | AB5: mandibles | AC5: Bite | AD5: 1 | AE5: 1.1 | AF5: HeadClaw | AG5: head claw | AH5: Scratch | AI5: 1 | AJ5: Invertebrate | AK5: 0 | AL5: BeetleLikeWithClaw | AM5: 0 | AN5: 1 | AO5: 1 | AP5: No | AQ5: 0 | AR5: Advanced | AS5: 1 | AT5: 0 | AU5: 0 | AV5: No | AW5: 0 | AX5: 0 | AY5: 0 | AZ5: 2 | BA5: 0 | BB5: 0 | BC5: 1 | BD5: 0 | BE5: 0 | BF5: 0 | BG5: 0.25 | BH5: 0.1 | BI5: 0.025 | BJ5: QuadrupedLow | BK5: 1 | BL5: 0 | BM5: 0
A6: Bird (STRONG BEAK, SMART) | B6: 1 | C6: 1.25 | D6: 0 | E6: 11 | F6: 0 | G6: 0 | H6: 1 | I6: 1 | J6: 1.09 | K6: Unknown | L6: 0 | M6: 0 | N6: StrongBeakBird | O6: 1 | P6: 1 | Q6: 1 | R6: Feet | S6: rear left claw, rear right claw | T6: Scratch | U6: No | V6: No | W6: No | X6: No | Y6: No | Z6: 0.8 | AA6: Beak | AB6: beak | AC6: Blunt | AD6: 0 | AE6: No | AF6: No | AG6: No | AH6: No | AI6: 1 | AJ6: Bird | AK6: 0 | AL6: Bird | AM6: 0 | AN6: 0 | AO6: 0 | AP6: 0.2 | AQ6: 0 | AR6: Advanced | AS6: 0 | AT6: 0 | AU6: 0 | AV6: No | AW6: 0 | AX6: 0 | AY6: 0 | AZ6: 0 | BA6: 0 | BB6: 1 | BC6: 0 | BD6: 0 | BE6: 1 | BF6: 1 | BG6: 1 | BH6: 0.1 | BI6: 0.025 | BJ6: Birdlike | BK6: 0 | BL6: 0 | BM6: 0
A7: Bird (STRONG BEAK, SMART, SCAVENGER) | B7: 1 | C7: 1.25 | D7: 0 | E7: 11 | F7: 0 | G7: 0 | H7: 1 | I7: 1 | J7: 1.09 | K7: Unknown | L7: 0 | M7: 0 | N7: StrongBeakBird | O7: 1 | P7: 1 | Q7: 1 | R7: Feet | S7: rear left claw, rear right claw | T7: Scratch | U7: No | V7: No | W7: No | X7: No | Y7: No | Z7: 0.8 | AA7: Beak | AB7: beak | AC7: Blunt | AD7: 0 | AE7: No | AF7: No | AG7: No | AH7: No | AI7: 1 | AJ7: Bird | AK7: 0 | AL7: Bird | AM7: 0 | AN7: 0 | AO7: 0 | AP7: 0.2 | AQ7: 0 | AR7: Advanced | AS7: 0 | AT7: 0 | AU7: 0 | AV7: No | AW7: 0 | AX7: 0 | AY7: 0 | AZ7: 1 | BA7: 0 | BB7: 1 | BC7: 0 | BD7: 0 | BE7: 1 | BF7: 1 | BG7: 1 | BH7: 0.1 | BI7: 0.025 | BJ7: Birdlike | BK7: 0 | BL7: 0 | BM7: 0
A8: Bird (STRONG BEAK) | B8: 0 | C8: 1.25 | D8: 0 | E8: 11 | F8: 0 | G8: 0 | H8: 1 | I8: 1 | J8: 1.09 | K8: Unknown | L8: 0 | M8: 0 | N8: StrongBeakBird | O8: 1 | P8: 1 | Q8: 1 | R8: Feet | S8: rear left claw, rear right claw | T8: Scratch | U8: No | V8: No | W8: No | X8: No | Y8: No | Z8: 0.8 | AA8: Beak | AB8: beak | AC8: Blunt | AD8: 0 | AE8: No | AF8: No | AG8: No | AH8: No | AI8: 1 | AJ8: Bird | AK8: 0 | AL8: Bird | AM8: 0 | AN8: 0 | AO8: 0 | AP8: No | AQ8: 0 | AR8: Intermediate | AS8: 0 | AT8: 0 | AU8: 0 | AV8: No | AW8: 0 | AX8: 0 | AY8: 0 | AZ8: 0 | BA8: 0 | BB8: 1 | BC8: 0 | BD8: 0 | BE8: 1 | BF8: 1 | BG8: 1 | BH8: 0 | BI8: 0 | BJ8: Birdlike | BK8: 0 | BL8: 0 | BM8: 0
A9: Bird (WATER) | B9: 1 | C9: 1.25 | D9: 1 | E9: 11 | F9: 0 | G9: 0 | H9: 1 | I9: 1 | J9: 1.09 | K9: Unknown | L9: 0 | M9: 0 | N9: Bird | O9: 1 | P9: 0 | Q9: No | R9: No | S9: No | T9: No | U9: No | V9: No | W9: No | X9: No | Y9: No | Z9: 0.8 | AA9: Beak | AB9: beak | AC9: Blunt | AD9: 0 | AE9: No | AF9: No | AG9: No | AH9: No | AI9: 1 | AJ9: Bird | AK9: 0 | AL9: Bird | AM9: 0 | AN9: 0 | AO9: 0 | AP9: No | AQ9: 0 | AR9: None | AS9: 0 | AT9: 1 | AU9: 1 | AV9: No | AW9: 0 | AX9: 0 | AY9: 0 | AZ9: 0 | BA9: 0 | BB9: 1 | BC9: 0 | BD9: 0 | BE9: 1 | BF9: 2 | BG9: 1 | BH9: 0 | BI9: 0 | BJ9: Birdlike | BK9: 0 | BL9: 0 | BM9: 0
A10: Bird (AGRESSIVE) | B10: 1 | C10: 1.5 | D10: 1 | E10: 11 | F10: 0 | G10: 0 | H10: 1 | I10: 1 | J10: 1.09 | K10: Unknown | L10: 0 | M10: 0 | N10: Bird | O10: 1 | P10: 1 | Q10: 0.9 | R10: Feet | S10: rear left claw, rear right claw | T10: Scratch | U10: No | V10: No | W10: No | X10: No | Y10: No | Z10: 1 | AA10: Beak | AB10: beak | AC10: Blunt | AD10: 0 | AE10: No | AF10: No | AG10: No | AH10: No | AI10: 1 | AJ10: Bird | AK10: 0 | AL10: Bird | AM10: 0 | AN10: 0.025 | AO10: 0.1 | AP10: No | AQ10: 0 | AR10: None | AS10: 0 | AT10: 0 | AU10: 0 | AV10: No | AW10: 0 | AX10: 0 | AY10: 0 | AZ10: 0 | BA10: 0 | BB10: 1 | BC10: 0 | BD10: 0 | BE10: 1 | BF10: 2 | BG10: 1 | BH10: 0 | BI10: 0 | BJ10: Birdlike | BK10: 0 | BL10: 0 | BM10: 0
A11: Bird (AGRESSIVE, SMART) | B11: 1 | C11: 1.25 | D11: 0 | E11: 11 | F11: 0 | G11: 0 | H11: 1 | I11: 1 | J11: 1.09 | K11: Unknown | L11: 0 | M11: 0 | N11: Bird | O11: 1 | P11: 1 | Q11: 1 | R11: Feet | S11: rear left claw, rear right claw | T11: Scratch | U11: No | V11: No | W11: No | X11: No | Y11: No | Z11: 0.8 | AA11: Beak | AB11: beak | AC11: Blunt | AD11: 0 | AE11: No | AF11: No | AG11: No | AH11: No | AI11: 1 | AJ11: Bird | AK11: 0 | AL11: Bird | AM11: 0 | AN11: 0.025 | AO11: 0.1 | AP11: 0.2 | AQ11: 0 | AR11: Intermediate | AS11: 0 | AT11: 0 | AU11: 0 | AV11: No | AW11: 0 | AX11: 0 | AY11: 0 | AZ11: 0 | BA11: 0 | BB11: 1 | BC11: 0 | BD11: 0 | BE11: 1 | BF11: 1 | BG11: 1 | BH11: 0.1 | BI11: 0.025 | BJ11: Birdlike | BK11: 0 | BL11: 0 | BM11: 0
A12: Bird (SCAVENGER) | B12: 1 | C12: 1.25 | D12: 0 | E12: 11 | F12: 0 | G12: 0 | H12: 1 | I12: 1 | J12: 1.09 | K12: Unknown | L12: 0 | M12: 0 | N12: Bird | O12: 1 | P12: 1 | Q12: 1 | R12: Feet | S12: rear left claw, rear right claw | T12: Scratch | U12: No | V12: No | W12: No | X12: No | Y12: No | Z12: 1 | AA12: Beak | AB12: beak | AC12: Blunt | AD12: 0 | AE12: No | AF12: No | AG12: No | AH12: No | AI12: 1 | AJ12: Bird | AK12: 0 | AL12: Bird | AM12: 0 | AN12: 0 | AO12: 0 | AP12: No | AQ12: 0 | AR12: None | AS12: 0 | AT12: 0 | AU12: 0 | AV12: No | AW12: 0 | AX12: 0 | AY12: 0 | AZ12: 1 | BA12: 0 | BB12: 1 | BC12: 0 | BD12: 0 | BE12: 1 | BF12: 2 | BG12: 1 | BH12: 0.1 | BI12: 0.025 | BJ12: Birdlike | BK12: 0 | BL12: 0 | BM12: 0
A13: Bird | B13: 0 | C13: 1.25 | D13: 1 | E13: 11 | F13: 0 | G13: 0 | H13: 1 | I13: 1 | J13: 1.09 | K13: Unknown | L13: 0 | M13: 0 | N13: Bird | O13: 1 | P13: 1 | Q13: 1 | R13: Feet | S13: rear left claw, rear right claw | T13: Scratch | U13: No | V13: No | W13: No | X13: No | Y13: No | Z13: 1 | AA13: Beak | AB13: beak | AC13: Blunt | AD13: 0 | AE13: No | AF13: No | AG13: No | AH13: No | AI13: 1 | AJ13: Bird | AK13: 0 | AL13: Bird | AM13: 0 | AN13: 0 | AO13: 0 | AP13: No | AQ13: 0 | AR13: None | AS13: 0 | AT13: 0 | AU13: 0 | AV13: No | AW13: 0 | AX13: 0 | AY13: 0 | AZ13: 0 | BA13: 0 | BB13: 1 | BC13: 0 | BD13: 0 | BE13: 1 | BF13: 2 | BG13: 1 | BH13: 0 | BI13: 0 | BJ13: Birdlike | BK13: 0 | BL13: 0 | BM13: 0
A14: Doglike (HYENA) | B14: 0 | C14: 1.25 | D14: 0 | E14: 1 | F14: 1 | G14: 0 | H14: =AVERAGE(21.6,12,10,13.1,30.5,38,15) -> 20.028571 | I14: =AVERAGE(0.54,1.5,1.5,0.86,0.24,0.54,0.85) -> 0.86142857 | J14: 1.09 | K14: =AVERAGE(0.13,0.106,0.134,0.129) -> 0.12475 | L14: 0 | M14: 0 | N14: Canid | O14: 0 | P14: 0 | Q14: No | R14: No | S14: No | T14: No | U14: No | V14: No | W14: No | X14: No | Y14: No | Z14: 0.8 | AA14: Teeth | AB14: canines | AC14: Bite | AD14: 0 | AE14: No | AF14: No | AG14: No | AH14: No | AI14: 1.2 | AJ14: Mammal | AK14: 0 | AL14: QuadrupedAnimalWithPawsAndTail | AM14: 1 | AN14: 0.1 | AO14: 0.3 | AP14: 1 | AQ14: 0 | AR14: Advanced | AS14: 1 | AT14: 0 | AU14: 0 | AV14: No | AW14: 0 | AX14: 0 | AY14: 0 | AZ14: 2 | BA14: 0 | BB14: 1 | BC14: 0 | BD14: 0 | BE14: 0 | BF14: 0 | BG14: 1 | BH14: 0.2 | BI14: 0.025 | BJ14: Quadruped | BK14: 0 | BL14: 0 | BM14: 0
A15: Doglike (CANID) | B15: 0 | C15: 1.25 | D15: 0 | E15: 1 | F15: 1 | G15: 0 | H15: =AVERAGE(21.6,12,10,13.1,30.5,38,15) -> 20.028571 | I15: =AVERAGE(0.54,1.5,1.5,0.86,0.24,0.54,0.85) -> 0.86142857 | J15: 1.09 | K15: =AVERAGE(0.13,0.106,0.134,0.129) -> 0.12475 | L15: 0 | M15: 0 | N15: Canid | O15: 0 | P15: 0 | Q15: No | R15: No | S15: No | T15: No | U15: No | V15: No | W15: No | X15: No | Y15: No | Z15: 0.8 | AA15: Teeth | AB15: canines | AC15: Bite | AD15: 0 | AE15: No | AF15: No | AG15: No | AH15: No | AI15: 1.2 | AJ15: Mammal | AK15: 0 | AL15: QuadrupedAnimalWithPawsAndTail | AM15: 1 | AN15: 0.1 | AO15: 0.3 | AP15: 1 | AQ15: 0 | AR15: Advanced | AS15: 1 | AT15: 0 | AU15: 0 | AV15: No | AW15: 0 | AX15: 0 | AY15: 0 | AZ15: 0 | BA15: 0 | BB15: 1 | BC15: 0 | BD15: 0 | BE15: 0 | BF15: 0 | BG15: 1 | BH15: 0.2 | BI15: 0.025 | BJ15: Quadruped | BK15: 0 | BL15: 0 | BM15: 0
A16: Crab | B16: 0 | C16: 1.5 | D16: 1 | E16: 1 | F16: 0 | G16: 0 | H16: 32 | I16: =H16/1000/13 -> 0.0024615385 | J16: 1.9 | K16: 0.32 | L16: 1 | M16: 1 | N16: No | O16: 1 | P16: 0 | Q16: No | R16: No | S16: No | T16: No | U16: No | V16: No | W16: No | X16: No | Y16: No | Z16: No | AA16: No | AB16: No | AC16: No | AD16: 1 | AE16: 1.2 | AF16: FrontLeftClaws, FrontRightClaws | AG16: left claw, right claw | AH16: Scratch | AI16: 1 | AJ16: Invertebrate | AK16: 0 | AL16: Crab | AM16: 0 | AN16: 0 | AO16: 0 | AP16: No | AQ16: 0 | AR16: None | AS16: 0 | AT16: 0 | AU16: 1 | AV16: No | AW16: 0 | AX16: 0 | AY16: 0 | AZ16: 1 | BA16: 0 | BB16: 0 | BC16: 1 | BD16: 0 | BE16: 0 | BF16: 1 | BG16: 0.25 | BH16: 0 | BI16: 0 | BJ16: QuadrupedLow | BK16: 0 | BL16: 0 | BM16: 0
A17: Crocodile | B17: 2 | C17: 1.1 | D17: 0 | E17: 1 | F17: 0 | G17: 0 | H17: =AVERAGE(65.2,57.2,43.4) -> 55.266667 | I17: =AVERAGE(31.29%,20.98%,15.21%) -> 0.22493333 | J17: 1.86 | K17: 0.2 | L17: 1 | M17: 0 | N17: Crocodile | O17: 0 | P17: 0 | Q17: No | R17: No | S17: No | T17: No | U17: No | V17: No | W17: No | X17: No | Y17: No | Z17: 0.95 | AA17: Teeth | AB17: teeth | AC17: Bite | AD17: 0 | AE17: No | AF17: No | AG17: No | AH17: No | AI17: 1.2 | AJ17: Reptile | AK17: 0 | AL17: QuadrupedAnimalWithClawsTailAndJowl | AM17: 0 | AN17: 0.1 | AO17: 0.3 | AP17: No | AQ17: 0 | AR17: None | AS17: 1 | AT17: 1 | AU17: 1 | AV17: No | AW17: 0 | AX17: 0 | AY17: 0 | AZ17: 2 | BA17: 0 | BB17: 0 | BC17: 1 | BD17: 0 | BE17: 0 | BF17: 1 | BG17: 0.25 | BH17: 0.1 | BI17: 0.025 | BJ17: QuadrupedLow | BK17: 0 | BL17: 0 | BM17: 0
A18: Elephant | B18: 2 | C18: 1 | D18: 0 | E18: 5 | F18: 0 | G18: 0 | H18: =AVERAGE(21.6,12,10,13.1,30.5,38,15) -> 20.028571 | I18: =AVERAGE(0.54,1.5,1.5,0.86,0.24,0.54,0.85) -> 0.86142857 | J18: 1.09 | K18: 0.08 | L18: 0 | M18: 0 | N18: No | O18: 0 | P18: 1 | Q18: 0.9 | R18: FrontLeftLeg, FrontRightLeg | S18: left foot, right foot | T18: Blunt | U18: 3 | V18: 0.7 | W18: TuskAttackTool | X18: tusk | Y18: Scratch | Z18: No | AA18: No | AB18: No | AC18: No | AD18: 0 | AE18: No | AF18: No | AG18: No | AH18: No | AI18: 1 | AJ18: Mammal | AK18: 1 | AL18: QuadrupedAnimalWithHoovesTusksAndTrunk | AM18: 0 | AN18: 0.025 | AO18: 0.3 | AP18: No | AQ18: 0 | AR18: Advanced | AS18: 0 | AT18: 0 | AU18: 0 | AV18: No | AW18: 0 | AX18: 0 | AY18: 0 | AZ18: 0 | BA18: 0 | BB18: 1 | BC18: 1 | BD18: 0 | BE18: 0 | BF18: 0 | BG18: 0.25 | BH18: 0.1 | BI18: 0.05 | BJ18: Quadruped | BK18: 0 | BL18: 0 | BM18: 0
A19: Catlike | B19: 2 | C19: 1.25 | D19: 0 | E19: 1 | F19: 1 | G19: 1 | H19: =AVERAGE(21.6,12,10,13.1,30.5,38,15) -> 20.028571 | I19: =AVERAGE(0.54,1.5,1.5,0.86,0.24,0.54,0.85) -> 0.86142857 | J19: 1.09 | K19: =AVERAGE(0.13,0.106,0.134,0.129) -> 0.12475 | L19: 0 | M19: 0 | N19: Felid | O19: 0 | P19: 0 | Q19: No | R19: No | S19: No | T19: No | U19: No | V19: No | W19: No | X19: No | Y19: No | Z19: 0.7 | AA19: Teeth | AB19: canines | AC19: Bite | AD19: 1 | AE19: 0.65 | AF19: FrontLeftPaw, FrontRightPaw | AG19: left claw, right claw | AH19: Scratch | AI19: 1.2 | AJ19: Mammal | AK19: 0 | AL19: QuadrupedAnimalWithPawsAndTail | AM19: 1 | AN19: 0.1 | AO19: 0.3 | AP19: 1 | AQ19: 0 | AR19: Intermediate | AS19: 1 | AT19: 0 | AU19: 0 | AV19: No | AW19: 0 | AX19: 0 | AY19: 0 | AZ19: 0 | BA19: 0 | BB19: 1 | BC19: 0 | BD19: 0 | BE19: 0 | BF19: 0 | BG19: 1.25 | BH19: 0.25 | BI19: 0.025 | BJ19: Quadruped | BK19: 0 | BL19: 0 | BM19: 0
A20: Catlike (PISCIVORE) | B20: 2 | C20: 1.25 | D20: 0 | E20: 1 | F20: 1 | G20: 1 | H20: =AVERAGE(21.6,12,10,13.1,30.5,38,15) -> 20.028571 | I20: =AVERAGE(0.54,1.5,1.5,0.86,0.24,0.54,0.85) -> 0.86142857 | J20: 1.09 | K20: =AVERAGE(0.13,0.106,0.134,0.129) -> 0.12475 | L20: 0 | M20: 0 | N20: Felid | O20: 0 | P20: 0 | Q20: No | R20: No | S20: No | T20: No | U20: No | V20: No | W20: No | X20: No | Y20: No | Z20: 0.7 | AA20: Teeth | AB20: canines | AC20: Bite | AD20: 1 | AE20: 0.65 | AF20: FrontLeftPaw, FrontRightPaw | AG20: left claw, right claw | AH20: Scratch | AI20: 1.2 | AJ20: Mammal | AK20: 0 | AL20: QuadrupedAnimalWithPawsAndTail | AM20: 1 | AN20: 0.1 | AO20: 0.3 | AP20: 1 | AQ20: 0 | AR20: Intermediate | AS20: 1 | AT20: 1 | AU20: 0 | AV20: No | AW20: 0 | AX20: 0 | AY20: 0 | AZ20: 0 | BA20: 0 | BB20: 1 | BC20: 0 | BD20: 0 | BE20: 0 | BF20: 0 | BG20: 1.25 | BH20: 0.25 | BI20: 0.025 | BJ20: Quadruped | BK20: 0 | BL20: 0 | BM20: 0
A21: Frog | B21: 0 | C21: 1 | D21: 1 | E21: 1 | F21: 0 | G21: 0 | H21: =AVERAGE(AVERAGE(14.84,16.45,15.67,11.41,11.56,11.45),11.5) -> 12.531667 | I21: =AVERAGE(63%,61.11%,59.19%,126.33%,114.23%,101.98%) -> 0.8764 | J21: 1.09 | K21: Unknown | L21: 0 | M21: 0 | N21: MiscEctotherms | O21: 1 | P21: 0 | Q21: No | R21: No | S21: No | T21: No | U21: No | V21: No | W21: No | X21: No | Y21: No | Z21: 1 | AA21: Teeth | AB21: teeth | AC21: Bite | AD21: 0 | AE21: No | AF21: No | AG21: No | AH21: No | AI21: 1 | AJ21: Amphibian | AK21: 0 | AL21: QuadrupedAnimalWithPaws | AM21: 0 | AN21: 0 | AO21: 0 | AP21: No | AQ21: 0 | AR21: None | AS21: 1 | AT21: 1 | AU21: 1 | AV21: No | AW21: 0 | AX21: 0 | AY21: 0 | AZ21: 0 | BA21: 1 | BB21: 0 | BC21: 0 | BD21: 0 | BE21: 0 | BF21: 0 | BG21: 0.5 | BH21: 0 | BI21: 0 | BJ21: QuadrupedLow | BK21: 0 | BL21: 0 | BM21: 0
A22: Camellike (LLAMA) | B22: 0 | C22: 0.7 | D22: 1 | E22: 5 | F22: 1 | G22: 0 | H22: =AVERAGE(21.6,12,10,13.1,30.5,38,15) -> 20.028571 | I22: =AVERAGE(0.54,1.5,1.5,0.86,0.24,0.54,0.85) -> 0.86142857 | J22: 1.09 | K22: Unknown | L22: 0 | M22: 0 | N22: StrongBitingHerbivore | O22: 0 | P22: 1 | Q22: 0.95 | R22: FrontLeftLeg, FrontRightLeg | S22: left hoof, right hoof | T22: Blunt | U22: No | V22: No | W22: No | X22: No | Y22: No | Z22: 1 | AA22: Teeth | AB22: teeth | AC22: Bite | AD22: 0 | AE22: No | AF22: No | AG22: No | AH22: No | AI22: 1 | AJ22: Mammal | AK22: 1 | AL22: QuadrupedAnimalWithHooves | AM22: 0 | AN22: 0 | AO22: 0 | AP22: No | AQ22: 0 | AR22: None | AS22: 0 | AT22: 0 | AU22: 0 | AV22: No | AW22: 0 | AX22: 0 | AY22: 0 | AZ22: 0 | BA22: 0 | BB22: 1 | BC22: 0 | BD22: 0 | BE22: 0 | BF22: 1 | BG22: 0.5 | BH22: 0 | BI22: 0 | BJ22: Quadruped | BK22: 0 | BL22: 0 | BM22: 0
A23: Camellike (CAMEL) | B23: 0 | C23: 0.7 | D23: 1 | E23: 5 | F23: 1 | G23: 0 | H23: =AVERAGE(21.6,12,10,13.1,30.5,38,15) -> 20.028571 | I23: =AVERAGE(0.54,1.5,1.5,0.86,0.24,0.54,0.85) -> 0.86142857 | J23: 1.09 | K23: Unknown | L23: 0 | M23: 0 | N23: StrongBitingHerbivore | O23: 0 | P23: 1 | Q23: 0.95 | R23: FrontLeftLeg, FrontRightLeg | S23: left hoof, right hoof | T23: Blunt | U23: No | V23: No | W23: No | X23: No | Y23: No | Z23: 1 | AA23: Teeth | AB23: teeth | AC23: Bite | AD23: 0 | AE23: No | AF23: No | AG23: No | AH23: No | AI23: 1 | AJ23: Mammal | AK23: 1 | AL23: QuadrupedAnimalWithHoovesAndHump | AM23: 0 | AN23: 0 | AO23: 0 | AP23: No | AQ23: 0 | AR23: None | AS23: 0 | AT23: 0 | AU23: 0 | AV23: No | AW23: 0 | AX23: 0 | AY23: 0 | AZ23: 0 | BA23: 0 | BB23: 1 | BC23: 0 | BD23: 0 | BE23: 0 | BF23: 1 | BG23: 0.5 | BH23: 0 | BI23: 0 | BJ23: Quadruped | BK23: 0 | BL23: 0 | BM23: 0
A24: Horse (WILD) | B24: 0 | C24: 1 | D24: 1 | E24: 5 | F24: 1 | G24: 0 | H24: =AVERAGE(21.6,12,10,13.1,30.5,38,15) -> 20.028571 | I24: =AVERAGE(0.54,1.5,1.5,0.86,0.24,0.54,0.85) -> 0.86142857 | J24: 1.09 | K24: Unknown | L24: 0 | M24: 0 | N24: StrongBitingHerbivore | O24: 0 | P24: 1 | Q24: 0.85 | R24: FrontLeftLeg, FrontRightLeg | S24: left hoof, right hoof | T24: Blunt | U24: No | V24: No | W24: No | X24: No | Y24: No | Z24: 1 | AA24: Teeth | AB24: teeth | AC24: Bite | AD24: 0 | AE24: No | AF24: No | AG24: No | AH24: No | AI24: 1 | AJ24: Mammal | AK24: 1 | AL24: QuadrupedAnimalWithHooves | AM24: 0 | AN24: 0 | AO24: 0 | AP24: 0.2 | AQ24: 0 | AR24: None | AS24: 0 | AT24: 0 | AU24: 0 | AV24: No | AW24: 0 | AX24: 0 | AY24: 0 | AZ24: 0 | BA24: 0 | BB24: 1 | BC24: 0 | BD24: 0 | BE24: 0 | BF24: 1 | BG24: 0.7 | BH24: 0 | BI24: 0 | BJ24: Quadruped | BK24: 0 | BL24: 0 | BM24: 0
A25: Horse | B25: 0 | C25: 0.7 | D25: 1 | E25: 5 | F25: 1 | G25: 0 | H25: =AVERAGE(21.6,12,10,13.1,30.5,38,15) -> 20.028571 | I25: =AVERAGE(0.54,1.5,1.5,0.86,0.24,0.54,0.85) -> 0.86142857 | J25: 1.09 | K25: Unknown | L25: 0 | M25: 0 | N25: StrongBitingHerbivore | O25: 0 | P25: 1 | Q25: 0.85 | R25: FrontLeftLeg, FrontRightLeg | S25: left hoof, right hoof | T25: Blunt | U25: No | V25: No | W25: No | X25: No | Y25: No | Z25: 1 | AA25: Teeth | AB25: teeth | AC25: Bite | AD25: 0 | AE25: No | AF25: No | AG25: No | AH25: No | AI25: 1 | AJ25: Mammal | AK25: 1 | AL25: QuadrupedAnimalWithHooves | AM25: 0 | AN25: 0 | AO25: 0 | AP25: 0.2 | AQ25: 0 | AR25: None | AS25: 0 | AT25: 0 | AU25: 0 | AV25: No | AW25: 0 | AX25: 0 | AY25: 0 | AZ25: 0 | BA25: 0 | BB25: 1 | BC25: 0 | BD25: 0 | BE25: 0 | BF25: 1 | BG25: 0.7 | BH25: 0 | BI25: 0 | BJ25: Quadruped | BK25: 0 | BL25: 0 | BM25: 0
A26: Lizard (IGUANA) | B26: 1 | C26: 1.3 | D26: 0 | E26: 1 | F26: 0 | G26: 0 | H26: 21 | I26: 0.85 | J26: 1.09 | K26: Unknown | L26: 0 | M26: 0 | N26: Lizard | O26: 0 | P26: 0 | Q26: No | R26: No | S26: No | T26: No | U26: No | V26: No | W26: No | X26: No | Y26: No | Z26: 0.9 | AA26: Teeth | AB26: teeth | AC26: Bite | AD26: 1 | AE26: 0.7 | AF26: FrontLeftClaws, FrontRightClaws | AG26: left claw, right claw | AH26: Scratch | AI26: 1.2 | AJ26: Reptile | AK26: 0 | AL26: QuadrupedAnimalWithClawsTailAndJowl | AM26: 0 | AN26: 0 | AO26: 0 | AP26: No | AQ26: 0 | AR26: None | AS26: 0 | AT26: 0 | AU26: 0 | AV26: No | AW26: 0 | AX26: 0 | AY26: 0 | AZ26: 0 | BA26: 0 | BB26: 0 | BC26: 0 | BD26: 0 | BE26: 0 | BF26: 0 | BG26: 0.5 | BH26: 0 | BI26: 0 | BJ26: QuadrupedLow | BK26: 0 | BL26: 0 | BM26: 0
A27: Lizard (MONITOR) | B27: 1 | C27: 1.3 | D27: 0 | E27: 1 | F27: 0 | G27: 0 | H27: 21 | I27: 0.85 | J27: 1.09 | K27: Unknown | L27: 0 | M27: 0 | N27: Lizard | O27: 0 | P27: 0 | Q27: No | R27: No | S27: No | T27: No | U27: No | V27: No | W27: No | X27: No | Y27: No | Z27: 0.85 | AA27: Teeth | AB27: teeth | AC27: ToxicBite | AD27: 1 | AE27: 0.7 | AF27: FrontLeftClaws, FrontRightClaws | AG27: left claw, right claw | AH27: Scratch | AI27: 1.2 | AJ27: Reptile | AK27: 0 | AL27: QuadrupedAnimalWithClawsTailAndJowl | AM27: 0 | AN27: 0.1 | AO27: 0.3 | AP27: No | AQ27: 0 | AR27: Intermediate | AS27: 1 | AT27: 0 | AU27: 0 | AV27: No | AW27: 0 | AX27: 0 | AY27: 0 | AZ27: 0 | BA27: 0 | BB27: 0 | BC27: 0 | BD27: 0 | BE27: 0 | BF27: 0 | BG27: 0.5 | BH27: 0.2 | BI27: 0.025 | BJ27: QuadrupedLow | BK27: 0 | BL27: 0 | BM27: 0
A28: Lizard (MONITOR, SCAVENGER) | B28: 1 | C28: 1.3 | D28: 0 | E28: 1 | F28: 0 | G28: 0 | H28: 21 | I28: 0.85 | J28: 1.09 | K28: Unknown | L28: 0 | M28: 0 | N28: Lizard | O28: 0 | P28: 0 | Q28: No | R28: No | S28: No | T28: No | U28: No | V28: No | W28: No | X28: No | Y28: No | Z28: 0.85 | AA28: Teeth | AB28: teeth | AC28: ToxicBite | AD28: 1 | AE28: 0.7 | AF28: FrontLeftClaws, FrontRightClaws | AG28: left claw, right claw | AH28: Scratch | AI28: 1.2 | AJ28: Reptile | AK28: 0 | AL28: QuadrupedAnimalWithClawsTailAndJowl | AM28: 0 | AN28: 0.1 | AO28: 0.3 | AP28: No | AQ28: 0 | AR28: Intermediate | AS28: 1 | AT28: 0 | AU28: 0 | AV28: No | AW28: 0 | AX28: 0 | AY28: 0 | AZ28: 1 | BA28: 0 | BB28: 0 | BC28: 0 | BD28: 0 | BE28: 0 | BF28: 0 | BG28: 0.5 | BH28: 0.2 | BI28: 0.025 | BJ28: QuadrupedLow | BK28: 0 | BL28: 0 | BM28: 0
A29: Marsupial (HERBIVOROUS) | B29: 1 | C29: 1.3 | D29: 0 | E29: 1 | F29: 0 | G29: 1 | H29: =AVERAGE(21.6,12,10,13.1,30.5,38,15) -> 20.028571 | I29: =AVERAGE(0.54,1.5,1.5,0.86,0.24,0.54,0.85) -> 0.86142857 | J29: 1.09 | K29: Unknown | L29: 0 | M29: 0 | N29: Rodent | O29: 0 | P29: 0 | Q29: No | R29: No | S29: No | T29: No | U29: No | V29: No | W29: No | X29: No | Y29: No | Z29: 0.95 | AA29: Teeth | AB29: teeth | AC29: Bite | AD29: 1 | AE29: 0.7 | AF29: FrontLeftPaw, FrontRightPaw | AG29: left claw, right claw | AH29: Scratch | AI29: 1 | AJ29: Mammal | AK29: 0 | AL29: QuadrupedAnimalWithPaws | AM29: 0 | AN29: 0 | AO29: 0 | AP29: No | AQ29: 0 | AR29: None | AS29: 0 | AT29: 0 | AU29: 0 | AV29: No | AW29: 0 | AX29: 0 | AY29: 0 | AZ29: 0 | BA29: 0 | BB29: 1 | BC29: 0 | BD29: 0 | BE29: 0 | BF29: 0 | BG29: 0.5 | BH29: 0 | BI29: 0 | BJ29: Quadruped | BK29: 0 | BL29: 0 | BM29: 0
A30: Marsupial (HERBIVOROUS, NO CLAWS) | B30: 1 | C30: 1 | D30: 0 | E30: 1 | F30: 0 | G30: 1 | H30: =AVERAGE(21.6,12,10,13.1,30.5,38,15) -> 20.028571 | I30: =AVERAGE(0.54,1.5,1.5,0.86,0.24,0.54,0.85) -> 0.86142857 | J30: 1.09 | K30: Unknown | L30: 0 | M30: 0 | N30: Rodent | O30: 0 | P30: 0 | Q30: No | R30: No | S30: No | T30: No | U30: No | V30: No | W30: No | X30: No | Y30: No | Z30: 0.95 | AA30: Teeth | AB30: teeth | AC30: Bite | AD30: 0 | AE30: No | AF30: No | AG30: No | AH30: No | AI30: 1 | AJ30: Mammal | AK30: 0 | AL30: QuadrupedAnimalWithPaws | AM30: 0 | AN30: 0 | AO30: 0 | AP30: No | AQ30: 0 | AR30: None | AS30: 0 | AT30: 0 | AU30: 0 | AV30: No | AW30: 0 | AX30: 0 | AY30: 0 | AZ30: 0 | BA30: 0 | BB30: 1 | BC30: 0 | BD30: 0 | BE30: 0 | BF30: 0 | BG30: 0.5 | BH30: 0 | BI30: 0 | BJ30: Quadruped | BK30: 0 | BL30: 0 | BM30: 0
A31: Marsupial (HERBIVOROUS, HOPPER) | B31: 1 | C31: 1.3 | D31: 1 | E31: 5 | F31: 0 | G31: 1 | H31: =AVERAGE(21.6,12,10,13.1,30.5,38,15) -> 20.028571 | I31: =AVERAGE(0.54,1.5,1.5,0.86,0.24,0.54,0.85) -> 0.86142857 | J31: 1.09 | K31: Unknown | L31: 0 | M31: 0 | N31: No | O31: 0 | P31: 1 | Q31: 1 | R31: RearLeftClaws, RearRightClaws | S31: left claw, rear right claw | T31: Scratch | U31: No | V31: No | W31: No | X31: No | Y31: No | Z31: No | AA31: No | AB31: No | AC31: No | AD31: 0 | AE31: No | AF31: No | AG31: No | AH31: No | AI31: 1 | AJ31: Mammal | AK31: 1 | AL31: BipedalAnimalWithPawsClawsAndTail | AM31: 0 | AN31: 0 | AO31: 0 | AP31: No | AQ31: 0 | AR31: None | AS31: 0 | AT31: 0 | AU31: 0 | AV31: No | AW31: 0 | AX31: 0 | AY31: 0 | AZ31: 0 | BA31: 0 | BB31: 1 | BC31: 0 | BD31: 0 | BE31: 1 | BF31: 0 | BG31: 0.7 | BH31: 0 | BI31: 0 | BJ31: Humanoid | BK31: 0 | BL31: 0 | BM31: 0
A32: MiscMammals | B32: 0 | C32: 1.2 | D32: 0 | E32: 1 | F32: 0 | G32: 0 | H32: =AVERAGE(21.6,12,10,13.1,30.5,38,15) -> 20.028571 | I32: =AVERAGE(0.54,1.5,1.5,0.86,0.24,0.54,0.85) -> 0.86142857 | J32: 1.09 | K32: Unknown | L32: 0 | M32: 0 | N32: MiscCarnivora | O32: 0 | P32: 0 | Q32: No | R32: No | S32: No | T32: No | U32: No | V32: No | W32: No | X32: No | Y32: No | Z32: 0.85 | AA32: Teeth | AB32: teeth | AC32: Bite | AD32: 0 | AE32: No | AF32: No | AG32: No | AH32: No | AI32: 1 | AJ32: Mammal | AK32: 0 | AL32: QuadrupedAnimalWithPaws | AM32: 0 | AN32: 0 | AO32: 0 | AP32: No | AQ32: 0 | AR32: None | AS32: 0 | AT32: 0 | AU32: 0 | AV32: No | AW32: 0 | AX32: 0 | AY32: 0 | AZ32: 0 | BA32: 0 | BB32: 1 | BC32: 0 | BD32: 0 | BE32: 0 | BF32: 0 | BG32: 0.7 | BH32: 0 | BI32: 0 | BJ32: Quadruped | BK32: 0 | BL32: 0 | BM32: 0
A33: ArmoredMammal | B33: 1 | C33: 1.2 | D33: 0 | E33: 1 | F33: 0 | G33: 0 | H33: =AVERAGE(65.5,108.7) -> 87.1 | I33: =AVERAGE(16.8%,11.9%) -> 0.1435 | J33: 0.96 | K33: 0.32 | L33: 1 | M33: 0 | N33: MiscCarnivora | O33: 0 | P33: 0 | Q33: No | R33: No | S33: No | T33: No | U33: No | V33: No | W33: No | X33: No | Y33: No | Z33: 0.85 | AA33: Teeth | AB33: teeth | AC33: Bite | AD33: 0 | AE33: No | AF33: No | AG33: No | AH33: No | AI33: 1 | AJ33: Mammal | AK33: 0 | AL33: QuadrupedAnimalWithPawsAndTail | AM33: 0 | AN33: 0 | AO33: 0 | AP33: No | AQ33: 0 | AR33: None | AS33: 0 | AT33: 0 | AU33: 0 | AV33: No | AW33: 0 | AX33: 0 | AY33: 0 | AZ33: 0 | BA33: 0 | BB33: 1 | BC33: 0 | BD33: 0 | BE33: 0 | BF33: 0 | BG33: 0.5 | BH33: 0 | BI33: 0 | BJ33: Quadruped | BK33: 0 | BL33: 0 | BM33: 0
A34: Kalisk | B34: 2 | C34: 2 | D34: 0 | E34: 1 | F34: 0 | G34: 0 | H34: 1000 | I34: 0.3 | J34: 1.3 | K34: Unknown | L34: 1 | M34: 0 | N34: MiscCarnivora | O34: 0 | P34: 0 | Q34: No | R34: No | S34: No | T34: No | U34: No | V34: No | W34: No | X34: No | Y34: No | Z34: 0.8 | AA34: Teeth | AB34: teeth | AC34: Bite | AD34: 1 | AE34: 0.65 | AF34: FrontLeftPaw, FrontRightPaw | AG34: left claw, right claw | AH34: Scratch | AI34: 1.5 | AJ34: Bird | AK34: 0 | AL34: QuadrupedAnimalWithPawsAndTail | AM34: 0 | AN34: 1 | AO34: 1 | AP34: No | AQ34: 0 | AR34: Advanced | AS34: 1 | AT34: 0 | AU34: 0 | AV34: No | AW34: 1 | AX34: 1 | AY34: 1 | AZ34: 0 | BA34: 0 | BB34: 1 | BC34: 0 | BD34: 0 | BE34: 0 | BF34: 0 | BG34: 1 | BH34: 0.25 | BI34: 0.05 | BJ34: Quadruped | BK34: 1 | BL34: 0 | BM34: 1
A35: Mustelid (NON-AQUATIC PISCIVORE) | B35: 1 | C35: 1.5 | D35: 0 | E35: 1 | F35: 1 | G35: 0 | H35: =AVERAGE(21.6,12,10,13.1,30.5,38,15) -> 20.028571 | I35: =AVERAGE(0.54,1.5,1.5,0.86,0.24,0.54,0.85) -> 0.86142857 | J35: 1.09 | K35: =AVERAGE(0.13,0.106,0.134,0.129) -> 0.12475 | L35: 0 | M35: 0 | N35: MiscCarnivora | O35: 0 | P35: 0 | Q35: No | R35: No | S35: No | T35: No | U35: No | V35: No | W35: No | X35: No | Y35: No | Z35: 0.8 | AA35: Teeth | AB35: canines | AC35: Bite | AD35: 1 | AE35: 0.65 | AF35: FrontLeftPaw, FrontRightPaw | AG35: left claw, right claw | AH35: Scratch | AI35: 1.2 | AJ35: Mammal | AK35: 0 | AL35: QuadrupedAnimalWithPawsAndTail | AM35: 1 | AN35: 0.1 | AO35: 0.3 | AP35: 0.5 | AQ35: 0 | AR35: Intermediate | AS35: 1 | AT35: 1 | AU35: 0 | AV35: No | AW35: 0 | AX35: 0 | AY35: 0 | AZ35: 0 | BA35: 0 | BB35: 1 | BC35: 0 | BD35: 0 | BE35: 0 | BF35: 0 | BG35: 1.1 | BH35: 0.2 | BI35: 0.025 | BJ35: QuadrupedLow | BK35: 0 | BL35: 0 | BM35: 0
A36: Mustelid (AQUATIC) | B36: 1 | C36: 1.5 | D36: 0 | E36: 1 | F36: 1 | G36: 0 | H36: =AVERAGE(21.6,12,10,13.1,30.5,38,15) -> 20.028571 | I36: =AVERAGE(0.54,1.5,1.5,0.86,0.24,0.54,0.85) -> 0.86142857 | J36: 1.09 | K36: =AVERAGE(0.13,0.106,0.134,0.129) -> 0.12475 | L36: 0 | M36: 0 | N36: MiscCarnivora | O36: 0 | P36: 0 | Q36: No | R36: No | S36: No | T36: No | U36: No | V36: No | W36: No | X36: No | Y36: No | Z36: 0.8 | AA36: Teeth | AB36: canines | AC36: Bite | AD36: 1 | AE36: 0.65 | AF36: FrontLeftPaw, FrontRightPaw | AG36: left claw, right claw | AH36: Scratch | AI36: 1.2 | AJ36: Mammal | AK36: 0 | AL36: QuadrupedAnimalWithPawsAndTail | AM36: 1 | AN36: 0.1 | AO36: 0.3 | AP36: 0.5 | AQ36: 0 | AR36: Intermediate | AS36: 1 | AT36: 1 | AU36: 1 | AV36: No | AW36: 0 | AX36: 0 | AY36: 0 | AZ36: 0 | BA36: 0 | BB36: 1 | BC36: 0 | BD36: 0 | BE36: 0 | BF36: 0 | BG36: 1.1 | BH36: 0.2 | BI36: 0.025 | BJ36: QuadrupedLow | BK36: 0 | BL36: 0 | BM36: 0
A37: Mustelid (SCAVENGER) | B37: 1 | C37: 1.5 | D37: 0 | E37: 1 | F37: 1 | G37: 0 | H37: =AVERAGE(21.6,12,10,13.1,30.5,38,15) -> 20.028571 | I37: =AVERAGE(0.54,1.5,1.5,0.86,0.24,0.54,0.85) -> 0.86142857 | J37: 1.09 | K37: =AVERAGE(0.13,0.106,0.134,0.129) -> 0.12475 | L37: 0 | M37: 0 | N37: MiscCarnivora | O37: 0 | P37: 0 | Q37: No | R37: No | S37: No | T37: No | U37: No | V37: No | W37: No | X37: No | Y37: No | Z37: 0.8 | AA37: Teeth | AB37: canines | AC37: Bite | AD37: 1 | AE37: 0.65 | AF37: FrontLeftPaw, FrontRightPaw | AG37: left claw, right claw | AH37: Scratch | AI37: 1.2 | AJ37: Mammal | AK37: 0 | AL37: QuadrupedAnimalWithPawsAndTail | AM37: 1 | AN37: 0.1 | AO37: 0.3 | AP37: 0.5 | AQ37: 0 | AR37: Intermediate | AS37: 1 | AT37: 0 | AU37: 0 | AV37: No | AW37: 0 | AX37: 0 | AY37: 0 | AZ37: 2 | BA37: 0 | BB37: 1 | BC37: 0 | BD37: 0 | BE37: 0 | BF37: 0 | BG37: 1.1 | BH37: 0.2 | BI37: 0.025 | BJ37: QuadrupedLow | BK37: 0 | BL37: 0 | BM37: 0
A38: Mustelid | B38: 1 | C38: 1.5 | D38: 0 | E38: 1 | F38: 1 | G38: 0 | H38: =AVERAGE(21.6,12,10,13.1,30.5,38,15) -> 20.028571 | I38: =AVERAGE(0.54,1.5,1.5,0.86,0.24,0.54,0.85) -> 0.86142857 | J38: 1.09 | K38: =AVERAGE(0.13,0.106,0.134,0.129) -> 0.12475 | L38: 0 | M38: 0 | N38: MiscCarnivora | O38: 0 | P38: 0 | Q38: No | R38: No | S38: No | T38: No | U38: No | V38: No | W38: No | X38: No | Y38: No | Z38: 0.8 | AA38: Teeth | AB38: canines | AC38: Bite | AD38: 1 | AE38: 0.65 | AF38: FrontLeftPaw, FrontRightPaw | AG38: left claw, right claw | AH38: Scratch | AI38: 1.2 | AJ38: Mammal | AK38: 0 | AL38: QuadrupedAnimalWithPawsAndTail | AM38: 1 | AN38: 0.1 | AO38: 0.3 | AP38: 0.5 | AQ38: 0 | AR38: Intermediate | AS38: 1 | AT38: 0 | AU38: 0 | AV38: No | AW38: 0 | AX38: 0 | AY38: 0 | AZ38: 0 | BA38: 0 | BB38: 1 | BC38: 0 | BD38: 0 | BE38: 0 | BF38: 0 | BG38: 1.1 | BH38: 0.2 | BI38: 0.025 | BJ38: QuadrupedLow | BK38: 0 | BL38: 0 | BM38: 0
A39: Pig | B39: 0 | C39: 1 | D39: 1 | E39: 5 | F39: 0 | G39: 0 | H39: =AVERAGE(21.6,12,10,13.1,30.5,38,15) -> 20.028571 | I39: =AVERAGE(0.54,1.5,1.5,0.86,0.24,0.54,0.85) -> 0.86142857 | J39: 1.09 | K39: Unknown | L39: 0 | M39: 0 | N39: Pig | O39: 0 | P39: 0 | Q39: No | R39: No | S39: No | T39: No | U39: No | V39: No | W39: No | X39: No | Y39: No | Z39: 1.1 | AA39: Teeth | AB39: teeth | AC39: Bite | AD39: 0 | AE39: No | AF39: No | AG39: No | AH39: No | AI39: 1 | AJ39: Mammal | AK39: 0 | AL39: QuadrupedAnimalWithHooves | AM39: 0 | AN39: 0 | AO39: 0 | AP39: No | AQ39: 1 | AR39: None | AS39: 0 | AT39: 0 | AU39: 0 | AV39: No | AW39: 0 | AX39: 0 | AY39: 0 | AZ39: 2 | BA39: 0 | BB39: 1 | BC39: 0 | BD39: 0 | BE39: 0 | BF39: 1 | BG39: 0.5 | BH39: 0 | BI39: 0 | BJ39: Quadruped | BK39: 0 | BL39: 0 | BM39: 0
A40: Pig (TUSKS) | B40: 0 | C40: 1 | D40: 1 | E40: 5 | F40: 0 | G40: 0 | H40: =AVERAGE(21.6,12,10,13.1,30.5,38,15) -> 20.028571 | I40: =AVERAGE(0.54,1.5,1.5,0.86,0.24,0.54,0.85) -> 0.86142857 | J40: 1.09 | K40: Unknown | L40: 0 | M40: 0 | N40: Pig | O40: 0 | P40: 0 | Q40: No | R40: No | S40: No | T40: No | U40: 1 | V40: 0.8 | W40: TuskAttackTool | X40: tusk | Y40: Scratch | Z40: 0.95 | AA40: Teeth | AB40: teeth | AC40: Bite | AD40: 0 | AE40: No | AF40: No | AG40: No | AH40: No | AI40: 1 | AJ40: Mammal | AK40: 0 | AL40: QuadrupedAnimalWithHoovesAndTusks | AM40: 0 | AN40: 0.025 | AO40: 0.1 | AP40: No | AQ40: 1 | AR40: None | AS40: 0 | AT40: 0 | AU40: 0 | AV40: No | AW40: 0 | AX40: 0 | AY40: 0 | AZ40: 2 | BA40: 0 | BB40: 1 | BC40: 0 | BD40: 0 | BE40: 0 | BF40: 0 | BG40: 0.5 | BH40: 0.1 | BI40: 0.025 | BJ40: Quadruped | BK40: 0 | BL40: 0 | BM40: 0
...

Sheet Base stats
A1: Common name | B1: Species | C1: Body mass (kg) | D1: Source | E1: Skill group | F1: Gestation (days) | G1: Age of first reproduction (years) | H1: Lifespan (years) | I1: Representative lifespan? | J1: Litter size | K1: Source | L1: Speed | M1: Source | N1: IsPollutionExclusive | O1: DomesticationLevel | P1: ExtraComfyTemperatureMin | Q1: ExtraComfyTemperatureMax | R1: Toxin resistance | S1: Bite force adjuster | T1: Teeth size adjuster | U1: Claw size (cm) | V1: Teeth size (cm) | W1: Horn or tusk size (cm) | X1: Horn/Antler/Tusks Male only | Y1: Diet | Z1: Health Multiplier | AA1: IgnoreAgressionSizeLimit | AB1: isUntameable | AC1: manhunterOnTameFailChance adjuster | AD1: manhunterOnDamageChance adjuster | AE1: Special trainables | AF1: wildGroupSize | AG1: LeatherDef | AH1: UseMeatFrom | AI1: IsPackAnimal | AJ1: IsMarine | AK1: IsExplosive | AL1: IsPremiumTame | AM1: IsRare | AN1: Swimming speed (Km/h) | AO1: Body surface area (cm^2) | AP1: Skin mass (kg) | AQ1: Skin thickness (mm) | AR1: Predicted ramming force (N) | AS1: Predicted punch/kick force (N) | AT1: Predicted bite force (N) | AU1: Predicted horn/tusk attack force (N) | AV1: AverageArmor | AW1: SkinAndMeatMarketValue | AX1: teethDamageAdjuster | AY1: clawDamageAdjuster | AZ1: tuskDamageAdjuster | BA1: generalDamageAdjuster | BB1: M_eff (bite) | BC1: M_eff (horn) | BD1: M_eff (head) | BE1: M (kick limb) | BF1: M (punch limb) | BG1: Ramming energy (j) | BH1: Punch energy (j) | BI1: Horn/Tusk energy (j) | BJ1: Bite energy (j) | BK1: V punch (head) | BL1: V punch (kick limb) | BM1: V punch (Horn/Tusk) | BN1: V punch (bite) | BO1: V punch (punch limb) | BP1: Claw/Punch surface area (cm^2) | BQ1: Horn or tusk surface area (cm^2) | BR1: Teeth surface area (cm^2) | BS1: Ramming pressure (kPa) | BT1: Claw/Punch pressure (kPa) | BU1: Horn or tusk pressure (kPa) | BV1: Bite pressure (kPa) | BW1: Extra CE attack interval | BX1: Extra CE damage adjuster
A2: Polar bear | B2: Ursus maritimus | C2: =AVERAGE(407.1,226.7) -> 316.9 | D2: Thiemann et al. (2011) https://doi.org/10.1002/jwmg.112 | E2: =Groups!$A$63 -> Bear | F2: 65 | G2: =1734/365 -> 4.7506849 | H2: 43.8 | I2: 0 | J2: 2 | K2: https://genomics.senescence.info/species/entry.php?species=Ursus_maritimus | L2: 40 | M2: https://biology.ucr.edu/people/faculty/Garland/Garl1983_JZL.pdf | N2: 0 | O2: 0 | P2: 0 | Q2: 0 | R2: Standard | S2: =_xlfn.XLOOKUP(B2,[1]TeethAdjusters!$A:$A,[1]BiteAdjusters!$C:$C,1) -> 0.92926025 | T2: =_xlfn.XLOOKUP(B2,[1]TeethAdjusters!$A:$A,[1]TeethAdjusters!$B:$B,1) -> 0.83672459 | U2: =MROUND(9.525,0.05) -> 9.55 | V2: =IF(AT2="No","No",IF(_xlfn.XLOOKUP(E2,Groups!A:A,Groups!AM:AM)=1,MROUND(EXP(0.3582*LN(C2)-0.2221)*T2,0.05),IF(_xlfn.XLOOKUP(E2,Groups!A:A,Groups!AM:AM)=2,MROUND(EXP(0.3582*LN(C2)-0.2221)*T2,0.05),"Need a formula"))) -> 5.25 | W2: No | X2: False | Y2: Carnivore | Z2: 1 | AA2: 0 | AB2: 0 | AC2: 0 | AD2: 0 | AE2: No | AF2: No | AG2: Leather_Bear | AH2: =Animals!$C$3 -> <li>Bear_Grizzly</li> | AI2: 0 | AJ2: 0 | AK2: 0 | AL2: 0 | AM2: 0 | AN2: Standard | AO2: =(0.111*C2^0.65)*10000 -> 46872.966 | AP2: =IFERROR(C2*_xlfn.XLOOKUP(E2,Groups!A:A,Groups!K:K),0.106*C2^0.94) -> 39.533275 | AQ2: =AP2*10000/(_xlfn.XLOOKUP(E2,Groups!A:A,Groups!J:J)*AO2) -> 7.7377352 | AR2: =EXP(0.8447*LN(C2)+3.996) -> 7046.4401 | AS2: =IF(_xlfn.XLOOKUP(E2,Groups!A:A,Groups!M:M)=1,EXP(0.7444*LN('Base stats'!C2)+6.5696),EXP(0.7927*LN('Base stats'!C2)+4.28)) -> 6938.4337 | AT2: =IF(_xlfn.XLOOKUP(E2,Groups!A:A,Groups!N:N)="No","No", IF(_xlfn.XLOOKUP(E2,Groups!A:A,Groups!N:N)="Crocodile",EXP(0.8129*LN(C2)+4.6742)*S2, IF(_xlfn.XLOOKUP(E2,Groups!A:A,Groups!N:N)="Felid",EXP(0.7843*LN(C2)+4.7073)*S2, IF(_xlfn.XLOOKUP(E2,Groups!A:A,Groups!N:N)="Canid",EXP(0.8367*LN(C2)+4.8763)*S2, IF(_xlfn.XLOOKUP(E2,Groups!A:A,Groups!N:N)="Pig",EXP(0.3439*LN(C2)+6.8519)*S2, IF(_xlfn.XLOOKUP(E2,Groups!A:A,Groups!N:N)="Rodent",EXP(0.5625*LN(C2)+4.3006)*S2, IF(_xlfn.XLOOKUP(E2,Groups!A:A,Groups!N:N)="Primate",EXP(0.7847*LN(C2)+3.4931)*S2, IF(_xlfn.XLOOKUP(E2,Groups!A:A,Groups!N:N)="MiscCarnivora",EXP(0.7486*LN(C2)+4.2207)*S2, IF(_xlfn.XLOOKUP(E2,Groups!A:A,Groups!N:N)="Lizard",EXP(0.7733*LN(C2)+5.5303)*S2, IF(_xlfn.XLOOKUP(E2,Groups!A:A,Groups!N:N)="Snake",50*C2^(2/3)*S2, IF(_xlfn.XLOOKUP(E2,Groups!A:A,Groups!N:N)="StrongBitingHerbivore",87.1133638856975*C2^(2/3)*S2, IF(_xlfn.XLOOKUP(E2,Groups!A:A,Groups!N:N)="MiscEctotherms",59.4316884072269*C2^(2/3)*S2, IF(_xlfn.XLOOKUP(E2,Groups!A:A,Groups!N:N)="StrongBeakBird",0.041*(C2*1000)^1.375*S2, IF(_xlfn.XLOOKUP(E2,Groups!A:A,Groups!N:N)="Bird",0.118*(C2*1000)^0.692*S2, IF(_xlfn.XLOOKUP(E2,Groups!A:A,Groups!N:N)="Insect",EXP(0.7444*LN(C2)+6.5696)*S2, IF(_xlfn.XLOOKUP(E2,Groups!A:A,Groups!N:N)="Theropod",EXP(0.6966*LN(C2)+4.158)*S2, "No")))))))))))))))) -> 4713.6189 | AU2: =IF(_xlfn.XLOOKUP(E2,Groups!A:A,Groups!U:U)=3,AS2,IF(_xlfn.XLOOKUP(E2,Groups!A:A,Groups!U:U)=2,AR2,AT2)) -> 4713.6189 | AV2: =IFERROR(AVERAGE(_xlfn.XLOOKUP(B2,Animals!B:B,Animals!N:N),_xlfn.XLOOKUP(B2,Animals!B:B,Animals!O:O)),0) -> 0 | AW2: =MROUND(40*Animals!AO2*_xlfn.XLOOKUP(AG2,Leathers!$A$2:$A$99,Leathers!$B$2:$B$99,0)+(140*_xlfn.XLOOKUP(B2,Animals!B:B,Animals!AO:AO)*2),5) -> 990 | AX2: =IFERROR(ROUND(SQRT(V2-1)*IF(_xlfn.XLOOKUP(E2,Groups!A:A,Groups!BF:BF)=0,2,1)*IF(_xlfn.XLOOKUP('Base stats'!E2,Groups!A:A,Groups!O:O)=0,1,0.1),1),0) -> 4.1 | AY2: =IFERROR(ROUND(SQRT(U2-1),1),0) -> 2.9 | AZ2: =IFERROR(ROUND(SQRT(W2),1),0) -> 0 | BA2: =ROUND( EXP(0.3582*LN(C2)-0.2221) * (0.75 + 0.25*(C2^4/(C2^4+10^4))), 1) -> 6.3 | BB2: =IF(_xlfn.XLOOKUP(E2,Groups!A:A,Groups!N:N)="Insect",BD2*2.5,IFERROR(AVERAGE(BD2,AT2/9.81/IF(OR(_xlfn.XLOOKUP(E2,Groups!A:A,Groups!N:N)="Pig",_xlfn.XLOOKUP(E2,Groups!A:A,Groups!N:N)="StrongBitingHerbivore"),20,25))*C2^-0.135,BD2)) -> 5.4953226 | BC2: =IF(W2="No","No",IF(_xlfn.XLOOKUP(E2,Groups!A:A,Groups!U:U)=1,'Base stats'!BB2,IF(OR(_xlfn.XLOOKUP(E2,Groups!A:A,Groups!BD:BD)=1,_xlfn.XLOOKUP(E2,Groups!A:A,Groups!U:U)=2),BD2,IF(_xlfn.XLOOKUP(B2,Animals!B:B,Animals!AO:AO)>4,AVERAGE(BD2,BF2),BF2)))) -> No | BD2: =(0.0392*C2^IF(OR(Y2="Herbivore",Y2="Dendrovore",Y2="OmnivoreRough"),0.889,0.966))*C2^-0.135 -> 4.6941012 | BE2: =IF(_xlfn.XLOOKUP(E2,Groups!A:A,Groups!BE:BE)=1,(0.048*C2^1.01)+(0.071*C2^1.03),0.071*C2^1.03)/IF(_xlfn.XLOOKUP(E2,Groups!A:A,Groups!M:M)=1,0.85,IF(OR(_xlfn.XLOOKUP(B2,Animals!B:B,Animals!AO:AO)>4,_xlfn.XLOOKUP(E2,Groups!A:A,Groups!BC:BC)=1),1.7,1))*C2^-0.25 -> 6.3383716 | BF2: =(0.048*C2^1.01)/IF(_xlfn.XLOOKUP(E2,Groups!A:A,Groups!M:M)=1,0.25,0.8)*C2^-0.25 -> 4.7736673 | BG2: =EXP(1.076*LN(AR2)-4.5397)*IF(_xlfn.XLOOKUP(E2,Groups!A:A,Groups!BC:BC)=1,1.25,IF(_xlfn.XLOOKUP(E2,Groups!A:A,Groups!BD:BD)=1,3.5,2.5)) -> 368.79822 | BH2: =EXP(1.076*LN(AS2)-4.5397)*IF(_xlfn.XLOOKUP(E2,Groups!A:A,Groups!M:M)=1,0.8,IF(_xlfn.XLOOKUP(E2,Groups!A:A,Groups!BC:BC)=1,1.3,3)) -> 435.26316 | BI2: =IF(W2="No","No",IF(_xlfn.XLOOKUP(E2,Groups!A:A,Groups!U:U)=1,'Base stats'!BJ2,IF(OR(_xlfn.XLOOKUP(E2,Groups!A:A,Groups!BD:BD)=1,_xlfn.XLOOKUP(E2,Groups!A:A,Groups!U:U)=2),BG2,BH2))*1.2) -> No | BJ2: =IFERROR(EXP(1.076*LN(AT2)-4.5397)*IF(_xlfn.XLOOKUP(E2,Groups!A:A,Groups!N:N)="Insect",1,IF(OR(_xlfn.XLOOKUP(E2,Groups!A:A,Groups!N:N)="Pig",_xlfn.XLOOKUP(E2,Groups!A:A,Groups!N:N)="StrongBitingHerbivore"),3.5,3.75)),"No") -> 358.91699 | BK2: =ROUNDDOWN(SQRT((2*BG2)/BD2),0) -> 12 | BL2: =ROUNDDOWN(SQRT((2*BH2)/BE2),0) -> 11 | BM2: =IF(W2="No","No",ROUNDDOWN(SQRT((2*BI2)/BC2),0)) -> No | BN2: =IF(V2="No","No",ROUNDDOWN(SQRT((2*BJ2)/BB2),0)) -> 11 | BO2: =ROUNDDOWN(SQRT((2*BH2)/BF2),0) -> 13 | BP2: {=IF(AND(_xlfn.XLOOKUP('Base stats'!E2,Groups!A:A,Groups!AD:AD=0),_xlfn.XLOOKUP('Base stats'!E2,Groups!A:A,Groups!P:P=0)),"No",IF(U2="No",AVERAGE(EXP(-0.57+0.99*LN(C2)),EXP(0.32+0.67*LN(C2)))/IF(_xlfn.XLOOKUP(E2,Groups!A:A,Groups!AD:AD)=1,10,2),(0.7354*C2^0.4078)*2/IF(_xlfn.XLOOKUP(E2,Groups!A:A,Groups!BK:BK)=1,1000,100)/IF(_xlfn.XLOOKUP(E2,Groups!A:A,Groups!AJ:AJ)="Photonozoa",3,1)))} -> 0.15396773 | BQ2: =IF(W2="No","No",IF(_xlfn.XLOOKUP(E2,Groups!A:A,Groups!BD:BD)=1,(AO2*5%),EXP(0.7354*LN(C2)^0.4078)*2/IF(_xlfn.XLOOKUP(E2,Groups!A:A,Groups!BL:BL)=1,1000,100)/IF(_xlfn.XLOOKUP(E2,Groups!A:A,Groups!AJ:AJ)="Photonozoa",3,1))) -> No | BR2: =IF(BJ2="No","No",IF(_xlfn.XLOOKUP(E2,Groups!A:A,Groups!BF:BF)=1,(0.0315*C2+2.1825)*2,(0.7354*C2^0.4078)*2)/IF(_xlfn.XLOOKUP(E2,Groups!A:A,Groups!BM:BM)=1,1000,100)/IF(_xlfn.XLOOKUP(E2,Groups!A:A,Groups!AJ:AJ)="Photonozoa",3,1)) -> 0.15396773 | BS2: =BG2/(AO2*5%) -> 0.15736074 | BT2: =IF(BP2="No","No",BH2/BP2) -> 2826.9765 | BU2: =IF(W2="No","No",BI2/BQ2) -> No | BV2: =IF(BJ2="No","No",BJ2/BR2) -> 2331.1183 | BW2: 0 | BX2: 1
A3: Grizzly | B3: Ursus arctos | C3: =AVERAGE(AVERAGE(268.7,174.9),AVERAGE(199.127,378.75)) -> 255.36925 | D3: Seryodkin et al. (2017) http://dx.doi.org/10.17217/2079-0333-2017-41-83-92 ; Troyer & Hensel (1969) The Brown Bear Of Kodiak Island. | E3: =Groups!$A$63 -> Bear | F3: 103 | G3: =1313/365 -> 3.5972603 | H3: 40 | I3: 0 | J3: 2 | K3: https://genomics.senescence.info/species/entry.php?species=Ursus_arctos | L3: 48 | M3: https://biology.ucr.edu/people/faculty/Garland/Garl1983_JZL.pdf | N3: 0 | O3: 0 | P3: 0 | Q3: 0 | R3: Standard | S3: =_xlfn.XLOOKUP(B3,[1]TeethAdjusters!$A:$A,[1]BiteAdjusters!$C:$C,1) -> 0.99503981 | T3: =_xlfn.XLOOKUP(B3,[1]TeethAdjusters!$A:$A,[1]TeethAdjusters!$B:$B,1) -> 0.79656343 | U3: =MROUND(7.62,0.05) -> 7.6 | V3: =IF(AT3="No","No",IF(_xlfn.XLOOKUP(E3,Groups!A:A,Groups!AM:AM)=1,MROUND(EXP(0.3582*LN(C3)-0.2221)*T3,0.05),IF(_xlfn.XLOOKUP(E3,Groups!A:A,Groups!AM:AM)=2,MROUND(EXP(0.3582*LN(C3)-0.2221)*T3,0.05),"Need a formula"))) -> 4.65 | W3: No | X3: False | Y3: Omnivore | Z3: 1 | AA3: 0 | AB3: 0 | AC3: 0 | AD3: 0 | AE3: No | AF3: No | AG3: Leather_Bear | AH3: No | AI3: 0 | AJ3: 0 | AK3: 0 | AL3: 0 | AM3: 0 | AN3: Standard | AO3: =(0.111*C3^0.65)*10000 -> 40736.393 | AP3: =IFERROR(C3*_xlfn.XLOOKUP(E3,Groups!A:A,Groups!K:K),0.106*C3^0.94) -> 31.857314 | AQ3: =AP3*10000/(_xlfn.XLOOKUP(E3,Groups!A:A,Groups!J:J)*AO3) -> 7.1746396 | AR3: =EXP(0.8447*LN(C3)+3.996) -> 5871.8651 | AS3: =IF(_xlfn.XLOOKUP(E3,Groups!A:A,Groups!M:M)=1,EXP(0.7444*LN('Base stats'!C3)+6.5696),EXP(0.7927*LN('Base stats'!C3)+4.28)) -> 5847.1325 | AT3: =IF(_xlfn.XLOOKUP(E3,Groups!A:A,Groups!N:N)="No","No", IF(_xlfn.XLOOKUP(E3,Groups!A:A,Groups!N:N)="Crocodile",EXP(0.8129*LN(C3)+4.6742)*S3, IF(_xlfn.XLOOKUP(E3,Groups!A:A,Groups!N:N)="Felid",EXP(0.7843*LN(C3)+4.7073)*S3, IF(_xlfn.XLOOKUP(E3,Groups!A:A,Groups!N:N)="Canid",EXP(0.8367*LN(C3)+4.8763)*S3, IF(_xlfn.XLOOKUP(E3,Groups!A:A,Groups!N:N)="Pig",EXP(0.3439*LN(C3)+6.8519)*S3, IF(_xlfn.XLOOKUP(E3,Groups!A:A,Groups!N:N)="Rodent",EXP(0.5625*LN(C3)+4.3006)*S3, IF(_xlfn.XLOOKUP(E3,Groups!A:A,Groups!N:N)="Primate",EXP(0.7847*LN(C3)+3.4931)*S3, IF(_xlfn.XLOOKUP(E3,Groups!A:A,Groups!N:N)="MiscCarnivora",EXP(0.7486*LN(C3)+4.2207)*S3, IF(_xlfn.XLOOKUP(E3,Groups!A:A,Groups!N:N)="Lizard",EXP(0.7733*LN(C3)+5.5303)*S3, IF(_xlfn.XLOOKUP(E3,Groups!A:A,Groups!N:N)="Snake",50*C3^(2/3)*S3, IF(_xlfn.XLOOKUP(E3,Groups!A:A,Groups!N:N)="StrongBitingHerbivore",87.1133638856975*C3^(2/3)*S3, IF(_xlfn.XLOOKUP(E3,Groups!A:A,Groups!N:N)="MiscEctotherms",59.4316884072269*C3^(2/3)*S3, IF(_xlfn.XLOOKUP(E3,Groups!A:A,Groups!N:N)="StrongBeakBird",0.041*(C3*1000)^1.375*S3, IF(_xlfn.XLOOKUP(E3,Groups!A:A,Groups!N:N)="Bird",0.118*(C3*1000)^0.692*S3, IF(_xlfn.XLOOKUP(E3,Groups!A:A,Groups!N:N)="Insect",EXP(0.7444*LN(C3)+6.5696)*S3, IF(_xlfn.XLOOKUP(E3,Groups!A:A,Groups!N:N)="Theropod",EXP(0.6966*LN(C3)+4.158)*S3, "No")))))))))))))))) -> 4294.1142 | AU3: =IF(_xlfn.XLOOKUP(E3,Groups!A:A,Groups!U:U)=3,AS3,IF(_xlfn.XLOOKUP(E3,Groups!A:A,Groups!U:U)=2,AR3,AT3)) -> 4294.1142 | AV3: =IFERROR(AVERAGE(_xlfn.XLOOKUP(B3,Animals!B:B,Animals!N:N),_xlfn.XLOOKUP(B3,Animals!B:B,Animals!O:O)),0) -> 0 | AW3: =MROUND(40*Animals!AO3*_xlfn.XLOOKUP(AG3,Leathers!$A$2:$A$99,Leathers!$B$2:$B$99,0)+(140*_xlfn.XLOOKUP(B3,Animals!B:B,Animals!AO:AO)*2),5) -> 880 | AX3: =IFERROR(ROUND(SQRT(V3-1)*IF(_xlfn.XLOOKUP(E3,Groups!A:A,Groups!BF:BF)=0,2,1)*IF(_xlfn.XLOOKUP('Base stats'!E3,Groups!A:A,Groups!O:O)=0,1,0.1),1),0) -> 3.8 | AY3: =IFERROR(ROUND(SQRT(U3-1),1),0) -> 2.6 | AZ3: =IFERROR(ROUND(SQRT(W3),1),0) -> 0 | BA3: =ROUND( EXP(0.3582*LN(C3)-0.2221) * (0.75 + 0.25*(C3^4/(C3^4+10^4))), 1) -> 5.8 | BB3: =IF(_xlfn.XLOOKUP(E3,Groups!A:A,Groups!N:N)="Insect",BD3*2.5,IFERROR(AVERAGE(BD3,AT3/9.81/IF(OR(_xlfn.XLOOKUP(E3,Groups!A:A,Groups!N:N)="Pig",_xlfn.XLOOKUP(E3,Groups!A:A,Groups!N:N)="StrongBitingHerbivore"),20,25))*C3^-0.135,BD3)) -> 5.0707493 | BC3: =IF(W3="No","No",IF(_xlfn.XLOOKUP(E3,Groups!A:A,Groups!U:U)=1,'Base stats'!BB3,IF(OR(_xlfn.XLOOKUP(E3,Groups!A:A,Groups!BD:BD)=1,_xlfn.XLOOKUP(E3,Groups!A:A,Groups!U:U)=2),BD3,IF(_xlfn.XLOOKUP(B3,Animals!B:B,Animals!AO:AO)>4,AVERAGE(BD3,BF3),BF3)))) -> No | BD3: =(0.0392*C3^IF(OR(Y3="Herbivore",Y3="Dendrovore",Y3="OmnivoreRough"),0.889,0.966))*C3^-0.135 -> 3.9232246 | BE3: =IF(_xlfn.XLOOKUP(E3,Groups!A:A,Groups!BE:BE)=1,(0.048*C3^1.01)+(0.071*C3^1.03),0.071*C3^1.03)/IF(_xlfn.XLOOKUP(E3,Groups!A:A,Groups!M:M)=1,0.85,IF(OR(_xlfn.XLOOKUP(B3,Animals!B:B,Animals!AO:AO)>4,_xlfn.XLOOKUP(E3,Groups!A:A,Groups!BC:BC)=1),1.7,1))*C3^-0.25 -> 5.3561146 | BF3: =(0.048*C3^1.01)/IF(_xlfn.XLOOKUP(E3,Groups!A:A,Groups!M:M)=1,0.25,0.8)*C3^-0.25 -> 4.0513465 | BG3: =EXP(1.076*LN(AR3)-4.5397)*IF(_xlfn.XLOOKUP(E3,Groups!A:A,Groups!BC:BC)=1,1.25,IF(_xlfn.XLOOKUP(E3,Groups!A:A,Groups!BD:BD)=1,3.5,2.5)) -> 303.09334 | BH3: =EXP(1.076*LN(AS3)-4.5397)*IF(_xlfn.XLOOKUP(E3,Groups!A:A,Groups!M:M)=1,0.8,IF(_xlfn.XLOOKUP(E3,Groups!A:A,Groups!BC:BC)=1,1.3,3)) -> 362.06387 | BI3: =IF(W3="No","No",IF(_xlfn.XLOOKUP(E3,Groups!A:A,Groups!U:U)=1,'Base stats'!BJ3,IF(OR(_xlfn.XLOOKUP(E3,Groups!A:A,Groups!BD:BD)=1,_xlfn.XLOOKUP(E3,Groups!A:A,Groups!U:U)=2),BG3,BH3))*1.2) -> No | BJ3: =IFERROR(EXP(1.076*LN(AT3)-4.5397)*IF(_xlfn.XLOOKUP(E3,Groups!A:A,Groups!N:N)="Insect",1,IF(OR(_xlfn.XLOOKUP(E3,Groups!A:A,Groups!N:N)="Pig",_xlfn.XLOOKUP(E3,Groups!A:A,Groups!N:N)="StrongBitingHerbivore"),3.5,3.75)),"No") -> 324.66584 | BK3: =ROUNDDOWN(SQRT((2*BG3)/BD3),0) -> 12 | BL3: =ROUNDDOWN(SQRT((2*BH3)/BE3),0) -> 11 | BM3: =IF(W3="No","No",ROUNDDOWN(SQRT((2*BI3)/BC3),0)) -> No | BN3: =IF(V3="No","No",ROUNDDOWN(SQRT((2*BJ3)/BB3),0)) -> 11 | BO3: =ROUNDDOWN(SQRT((2*BH3)/BF3),0) -> 13 | BP3: {=IF(AND(_xlfn.XLOOKUP('Base stats'!E3,Groups!A:A,Groups!AD:AD=0),_xlfn.XLOOKUP('Base stats'!E3,Groups!A:A,Groups!P:P=0)),"No",IF(U3="No",AVERAGE(EXP(-0.57+0.99*LN(C3)),EXP(0.32+0.67*LN(C3)))/IF(_xlfn.XLOOKUP(E3,Groups!A:A,Groups!AD:AD)=1,10,2),(0.7354*C3^0.4078)*2/IF(_xlfn.XLOOKUP(E3,Groups!A:A,Groups!BK:BK)=1,1000,100)/IF(_xlfn.XLOOKUP(E3,Groups!A:A,Groups!AJ:AJ)="Photonozoa",3,1)))} -> 0.14099281 | BQ3: =IF(W3="No","No",IF(_xlfn.XLOOKUP(E3,Groups!A:A,Groups!BD:BD)=1,(AO3*5%),EXP(0.7354*LN(C3)^0.4078)*2/IF(_xlfn.XLOOKUP(E3,Groups!A:A,Groups!BL:BL)=1,1000,100)/IF(_xlfn.XLOOKUP(E3,Groups!A:A,Groups!AJ:AJ)="Photonozoa",3,1))) -> No | BR3: =IF(BJ3="No","No",IF(_xlfn.XLOOKUP(E3,Groups!A:A,Groups!BF:BF)=1,(0.0315*C3+2.1825)*2,(0.7354*C3^0.4078)*2)/IF(_xlfn.XLOOKUP(E3,Groups!A:A,Groups!BM:BM)=1,1000,100)/IF(_xlfn.XLOOKUP(E3,Groups!A:A,Groups!AJ:AJ)="Photonozoa",3,1)) -> 0.14099281 | BS3: =BG3/(AO3*5%) -> 0.14880716 | BT3: =IF(BP3="No","No",BH3/BP3) -> 2567.9598 | BU3: =IF(W3="No","No",BI3/BQ3) -> No | BV3: =IF(BJ3="No","No",BJ3/BR3) -> 2302.712 | BW3: 0 | BX3: 1
A4: Raccoon | B4: Procyon lotor | C4: 6 | D4: https://genomics.senescence.info/species/entry.php?species=Procyon_lotor | E4: =Groups!$A$64 -> Raccoon | F4: 63 | G4: =365/365 -> 1 | H4: 21 | I4: 0 | J4: 4 | K4: https://genomics.senescence.info/species/entry.php?species=Procyon_lotor | L4: 24 | M4: https://biology.ucr.edu/people/faculty/Garland/Garl1983_JZL.pdf | N4: 0 | O4: 0 | P4: 0 | Q4: 0 | R4: 0.8 | S4: =_xlfn.XLOOKUP(B4,[1]TeethAdjusters!$A:$A,[1]BiteAdjusters!$C:$C,1) -> 0.69303335 | T4: =_xlfn.XLOOKUP(B4,[1]TeethAdjusters!$A:$A,[1]TeethAdjusters!$B:$B,1) -> 1.1605025 | U4: =MROUND(1.27,0.05) -> 1.25 | V4: =IF(AT4="No","No",IF(_xlfn.XLOOKUP(E4,Groups!A:A,Groups!AM:AM)=1,MROUND(EXP(0.3582*LN(C4)-0.2221)*T4,0.05),IF(_xlfn.XLOOKUP(E4,Groups!A:A,Groups!AM:AM)=2,MROUND(EXP(0.3582*LN(C4)-0.2221)*T4,0.05),"Need a formula"))) -> 1.75 | W4: No | X4: False | Y4: Omnivore | Z4: 1 | AA4: 0 | AB4: 0 | AC4: 0 | AD4: 0 | AE4: No | AF4: No | AG4: Leather_Light | AH4: No | AI4: 0 | AJ4: 0 | AK4: 0 | AL4: 0 | AM4: 0 | AN4: Standard | AO4: =(0.111*C4^0.65)*10000 -> 3557.3065 | AP4: =IFERROR(C4*_xlfn.XLOOKUP(E4,Groups!A:A,Groups!K:K),0.106*C4^0.94) -> 0.7485 | AQ4: =AP4*10000/(_xlfn.XLOOKUP(E4,Groups!A:A,Groups!J:J)*AO4) -> 1.9303854 | AR4: =EXP(0.8447*LN(C4)+3.996) -> 247.02739 | AS4: =IF(_xlfn.XLOOKUP(E4,Groups!A:A,Groups!M:M)=1,EXP(0.7444*LN('Base stats'!C4)+6.5696),EXP(0.7927*LN('Base stats'!C4)+4.28)) -> 298.96537 | AT4: =IF(_xlfn.XLOOKUP(E4,Groups!A:A,Groups!N:N)="No","No", IF(_xlfn.XLOOKUP(E4,Groups!A:A,Groups!N:N)="Crocodile",EXP(0.8129*LN(C4)+4.6742)*S4, IF(_xlfn.XLOOKUP(E4,Groups!A:A,Groups!N:N)="Felid",EXP(0.7843*LN(C4)+4.7073)*S4, IF(_xlfn.XLOOKUP(E4,Groups!A:A,Groups!N:N)="Canid",EXP(0.8367*LN(C4)+4.8763)*S4, IF(_xlfn.XLOOKUP(E4,Groups!A:A,Groups!N:N)="Pig",EXP(0.3439*LN(C4)+6.8519)*S4, IF(_xlfn.XLOOKUP(E4,Groups!A:A,Groups!N:N)="Rodent",EXP(0.5625*LN(C4)+4.3006)*S4, IF(_xlfn.XLOOKUP(E4,Groups!A:A,Groups!N:N)="Primate",EXP(0.7847*LN(C4)+3.4931)*S4, IF(_xlfn.XLOOKUP(E4,Groups!A:A,Groups!N:N)="MiscCarnivora",EXP(0.7486*LN(C4)+4.2207)*S4, IF(_xlfn.XLOOKUP(E4,Groups!A:A,Groups!N:N)="Lizard",EXP(0.7733*LN(C4)+5.5303)*S4, IF(_xlfn.XLOOKUP(E4,Groups!A:A,Groups!N:N)="Snake",50*C4^(2/3)*S4, IF(_xlfn.XLOOKUP(E4,Groups!A:A,Groups!N:N)="StrongBitingHerbivore",87.1133638856975*C4^(2/3)*S4, IF(_xlfn.XLOOKUP(E4,Groups!A:A,Groups!N:N)="MiscEctotherms",59.4316884072269*C4^(2/3)*S4, IF(_xlfn.XLOOKUP(E4,Groups!A:A,Groups!N:N)="StrongBeakBird",0.041*(C4*1000)^1.375*S4, IF(_xlfn.XLOOKUP(E4,Groups!A:A,Groups!N:N)="Bird",0.118*(C4*1000)^0.692*S4, IF(_xlfn.XLOOKUP(E4,Groups!A:A,Groups!N:N)="Insect",EXP(0.7444*LN(C4)+6.5696)*S4, IF(_xlfn.XLOOKUP(E4,Groups!A:A,Groups!N:N)="Theropod",EXP(0.6966*LN(C4)+4.158)*S4, "No")))))))))))))))) -> 180.42839 | AU4: =IF(_xlfn.XLOOKUP(E4,Groups!A:A,Groups!U:U)=3,AS4,IF(_xlfn.XLOOKUP(E4,Groups!A:A,Groups!U:U)=2,AR4,AT4)) -> 180.42839 | AV4: =IFERROR(AVERAGE(_xlfn.XLOOKUP(B4,Animals!B:B,Animals!N:N),_xlfn.XLOOKUP(B4,Animals!B:B,Animals!O:O)),0) -> 0 | AW4: =MROUND(40*Animals!AO4*_xlfn.XLOOKUP(AG4,Leathers!$A$2:$A$99,Leathers!$B$2:$B$99,0)+(140*_xlfn.XLOOKUP(B4,Animals!B:B,Animals!AO:AO)*2),5) -> 125 | AX4: =IFERROR(ROUND(SQRT(V4-1)*IF(_xlfn.XLOOKUP(E4,Groups!A:A,Groups!BF:BF)=0,2,1)*IF(_xlfn.XLOOKUP('Base stats'!E4,Groups!A:A,Groups!O:O)=0,1,0.1),1),0) -> 1.7 | AY4: =IFERROR(ROUND(SQRT(U4-1),1),0) -> 0.5 | AZ4: =IFERROR(ROUND(SQRT(W4),1),0) -> 0 | BA4: =ROUND( EXP(0.3582*LN(C4)-0.2221) * (0.75 + 0.25*(C4^4/(C4^4+10^4))), 1) -> 1.2 | BB4: =IF(_xlfn.XLOOKUP(E4,Groups!A:A,Groups!N:N)="Insect",BD4*2.5,IFERROR(AVERAGE(BD4,AT4/9.81/IF(OR(_xlfn.XLOOKUP(E4,Groups!A:A,Groups!N:N)="Pig",_xlfn.XLOOKUP(E4,Groups!A:A,Groups!N:N)="StrongBitingHerbivore"),20,25))*C4^-0.135,BD4)) -> 0.35702235 | BC4: =IF(W4="No","No",IF(_xlfn.XLOOKUP(E4,Groups!A:A,Groups!U:U)=1,'Base stats'!BB4,IF(OR(_xlfn.XLOOKUP(E4,Groups!A:A,Groups!BD:BD)=1,_xlfn.XLOOKUP(E4,Groups!A:A,Groups!U:U)=2),BD4,IF(_xlfn.XLOOKUP(B4,Animals!B:B,Animals!AO:AO)>4,AVERAGE(BD4,BF4),BF4)))) -> No | BD4: =(0.0392*C4^IF(OR(Y4="Herbivore",Y4="Dendrovore",Y4="OmnivoreRough"),0.889,0.966))*C4^-0.135 -> 0.17375198 | BE4: =IF(_xlfn.XLOOKUP(E4,Groups!A:A,Groups!BE:BE)=1,(0.048*C4^1.01)+(0.071*C4^1.03),0.071*C4^1.03)/IF(_xlfn.XLOOKUP(E4,Groups!A:A,Groups!M:M)=1,0.85,IF(OR(_xlfn.XLOOKUP(B4,Animals!B:B,Animals!AO:AO)>4,_xlfn.XLOOKUP(E4,Groups!A:A,Groups!BC:BC)=1),1.7,1))*C4^-0.25 -> 0.28722109 | BF4: =(0.048*C4^1.01)/IF(_xlfn.XLOOKUP(E4,Groups!A:A,Groups!M:M)=1,0.25,0.8)*C4^-0.25 -> 0.23417806 | BG4: =EXP(1.076*LN(AR4)-4.5397)*IF(_xlfn.XLOOKUP(E4,Groups!A:A,Groups!BC:BC)=1,1.25,IF(_xlfn.XLOOKUP(E4,Groups!A:A,Groups!BD:BD)=1,3.5,2.5)) -> 10.022293 | BH4: =EXP(1.076*LN(AS4)-4.5397)*IF(_xlfn.XLOOKUP(E4,Groups!A:A,Groups!M:M)=1,0.8,IF(_xlfn.XLOOKUP(E4,Groups!A:A,Groups!BC:BC)=1,1.3,3)) -> 14.768033 | BI4: =IF(W4="No","No",IF(_xlfn.XLOOKUP(E4,Groups!A:A,Groups!U:U)=1,'Base stats'!BJ4,IF(OR(_xlfn.XLOOKUP(E4,Groups!A:A,Groups!BD:BD)=1,_xlfn.XLOOKUP(E4,Groups!A:A,Groups!U:U)=2),BG4,BH4))*1.2) -> No | BJ4: =IFERROR(EXP(1.076*LN(AT4)-4.5397)*IF(_xlfn.XLOOKUP(E4,Groups!A:A,Groups!N:N)="Insect",1,IF(OR(_xlfn.XLOOKUP(E4,Groups!A:A,Groups!N:N)="Pig",_xlfn.XLOOKUP(E4,Groups!A:A,Groups!N:N)="StrongBitingHerbivore"),3.5,3.75)),"No") -> 10.72133 | BK4: =ROUNDDOWN(SQRT((2*BG4)/BD4),0) -> 10 | BL4: =ROUNDDOWN(SQRT((2*BH4)/BE4),0) -> 10 | BM4: =IF(W4="No","No",ROUNDDOWN(SQRT((2*BI4)/BC4),0)) -> No | BN4: =IF(V4="No","No",ROUNDDOWN(SQRT((2*BJ4)/BB4),0)) -> 7 | BO4: =ROUNDDOWN(SQRT((2*BH4)/BF4),0) -> 11 | BP4: {=IF(AND(_xlfn.XLOOKUP('Base stats'!E4,Groups!A:A,Groups!AD:AD=0),_xlfn.XLOOKUP('Base stats'!E4,Groups!A:A,Groups!P:P=0)),"No",IF(U4="No",AVERAGE(EXP(-0.57+0.99*LN(C4)),EXP(0.32+0.67*LN(C4)))/IF(_xlfn.XLOOKUP(E4,Groups!A:A,Groups!AD:AD)=1,10,2),(0.7354*C4^0.4078)*2/IF(_xlfn.XLOOKUP(E4,Groups!A:A,Groups!BK:BK)=1,1000,100)/IF(_xlfn.XLOOKUP(E4,Groups!A:A,Groups!AJ:AJ)="Photonozoa",3,1)))} -> 0.030541032 | BQ4: =IF(W4="No","No",IF(_xlfn.XLOOKUP(E4,Groups!A:A,Groups!BD:BD)=1,(AO4*5%),EXP(0.7354*LN(C4)^0.4078)*2/IF(_xlfn.XLOOKUP(E4,Groups!A:A,Groups!BL:BL)=1,1000,100)/IF(_xlfn.XLOOKUP(E4,Groups!A:A,Groups!AJ:AJ)="Photonozoa",3,1))) -> No | BR4: =IF(BJ4="No","No",IF(_xlfn.XLOOKUP(E4,Groups!A:A,Groups!BF:BF)=1,(0.0315*C4+2.1825)*2,(0.7354*C4^0.4078)*2)/IF(_xlfn.XLOOKUP(E4,Groups!A:A,Groups!BM:BM)=1,1000,100)/IF(_xlfn.XLOOKUP(E4,Groups!A:A,Groups!AJ:AJ)="Photonozoa",3,1)) -> 0.030541032 | BS4: =BG4/(AO4*5%) -> 0.056347648 | BT4: =IF(BP4="No","No",BH4/BP4) -> 483.5473 | BU4: =IF(W4="No","No",BI4/BQ4) -> No | BV4: =IF(BJ4="No","No",BJ4/BR4) -> 351.04675 | BW4: 0 | BX4: 1
