Workbook

Sheet Bite force
A1: Bite force
A2: Species | B2: Weight (kg) | C2: Max. Bite force (N) | D2: Isometric bite force (N) | E2: Method | F2: Source | G2: ln weight (kg) | H2: ln max. Bite force (N) | I2: Relative bite force
A3: Suids
A4: Sus scrofa | B4: 30 | C4: 2783.1 | D4: =C4*(1/B4)^(2/3) -> 288.25796 | E4: In vivo | F4: https://pmc.ncbi.nlm.nih.gov/articles/PMC8364746/ | G4: =LN(B4) -> 3.4011974 | H4: =LN(C4) -> 7.9313207 | I4: =C4/EXP(0.3439*LN(B4)+6.8519) -> 0.91370174
A5: Sus scrofa | B5: 30 | C5: 2914.5 | D5: =C5*(1/B5)^(2/3) -> 301.86764 | E5: In vivo | F5: https://pmc.ncbi.nlm.nih.gov/articles/PMC8364746/ | G5: =LN(B5) -> 3.4011974 | H5: =LN(C5) -> 7.9774536 | I5: =C5/EXP(0.3439*LN(B5)+6.8519) -> 0.95684083
A6: Sus scrofa | B6: 60 | C6: 4335.5 | D6: =C6*(1/B6)^(2/3) -> 282.88181 | E6: In vivo | F6: https://pmc.ncbi.nlm.nih.gov/articles/PMC8364746/ | G6: =LN(B6) -> 4.0943446 | H6: =LN(C6) -> 8.3745922 | I6: =C6/EXP(0.3439*LN(B6)+6.8519) -> 1.1214776
A7: Sus scrofa | B7: 38 | C7: 2489.9 | D7: =C7*(1/B7)^(2/3) -> 220.28901 | E7: In vivo | F7: https://pmc.ncbi.nlm.nih.gov/articles/PMC8364746/ | G7: =LN(B7) -> 3.6375862 | H7: =LN(C7) -> 7.8199978 | I7: =C7/EXP(0.3439*LN(B7)+6.8519) -> 0.75361922
A8: Sus scrofa | B8: 30 | C8: 2543.8 | D8: =C8*(1/B8)^(2/3) -> 263.4726 | E8: In vivo | F8: https://pmc.ncbi.nlm.nih.gov/articles/PMC8364746/ | G8: =LN(B8) -> 3.4011974 | H8: =LN(C8) -> 7.8414143 | I8: =C8/EXP(0.3439*LN(B8)+6.8519) -> 0.83513869
A9: Sus scrofa | B9: 37 | C9: 3687.3 | D9: =C9*(1/B9)^(2/3) -> 332.07842 | E9: In vivo | F9: https://pmc.ncbi.nlm.nih.gov/articles/PMC8364746/ | G9: =LN(B9) -> 3.6109179 | H9: =LN(C9) -> 8.2126498 | I9: =C9/EXP(0.3439*LN(B9)+6.8519) -> 1.1263193
A10: Sus scrofa | B10: 90 | C10: 4838.6 | D10: =C10*(1/B10)^(2/3) -> 240.93028 | E10: In vivo | F10: https://pmc.ncbi.nlm.nih.gov/articles/PMC8364746/ | G10: =LN(B10) -> 4.4998097 | H10: =LN(C10) -> 8.4843807 | I10: =C10/EXP(0.3439*LN(B10)+6.8519) -> 1.0887129
A11: Tayassu pecari | B11: 43 | C11: 3162.6 | D11: =C11*(1/B11)^(2/3) -> 257.67085 | E11: In vivo | F11: https://pmc.ncbi.nlm.nih.gov/articles/PMC8364746/ | G11: =LN(B11) -> 3.7612001 | H11: =LN(C11) -> 8.0591498 | I11: =C11/EXP(0.3439*LN(B11)+6.8519) -> 0.91738599
A12: Tayassu pecari | B12: 32 | C12: 3510.8 | D12: =C12*(1/B12)^(2/3) -> 348.31548 | E12: In vivo | F12: https://pmc.ncbi.nlm.nih.gov/articles/PMC8364746/ | G12: =LN(B12) -> 3.4657359 | H12: =LN(C12) -> 8.1635992 | I12: =C12/EXP(0.3439*LN(B12)+6.8519) -> 1.1273082
A13: Pecari tajacu | B13: 16 | C13: 2489.9 | D13: =C13*(1/B13)^(2/3) -> 392.13468 | E13: In vivo | F13: https://pmc.ncbi.nlm.nih.gov/articles/PMC8364746/ | G13: =LN(B13) -> 2.7725887 | H13: =LN(C13) -> 7.8199978 | I13: =C13/EXP(0.3439*LN(B13)+6.8519) -> 1.0147117
A14: Pecari tajacu | B14: 19.5 | C14: 3302.9 | D14: =C14*(1/B14)^(2/3) -> 455.9029 | E14: In vivo | F14: https://pmc.ncbi.nlm.nih.gov/articles/PMC8364746/ | G14: =LN(B14) -> 2.9704145 | H14: =LN(C14) -> 8.1025561 | I14: =C14/EXP(0.3439*LN(B14)+6.8519) -> 1.2575063
A15: Felids
A16: Caracal caracal | B16: 16.59 | C16: 1008.9 | D16: =C16*(1/B16)^(2/3) -> 155.10193 | E16: PCSA | F16: https://anatomypubs.onlinelibrary.wiley.com/doi/10.1002/ar.22518 | G16: =LN(B16) -> 2.8088001 | H16: =LN(C16) -> 6.9166159 | I16: =C16/EXP(0.9087*LN(B16)+4.3479) -> 1.0164938
A17: Leptailurus serval | B17: 13.9 | C17: 909.6 | D17: =C17*(1/B17)^(2/3) -> 157.34052 | E17: PCSA | F17: https://anatomypubs.onlinelibrary.wiley.com/doi/10.1002/ar.22518 | G17: =LN(B17) -> 2.6318888 | H17: =LN(C17) -> 6.8130049 | I17: =C17/EXP(0.9087*LN(B17)+4.3479) -> 1.0762767
A18: Leopardus pardalis | B18: 11.59 | C18: 1017 | D18: =C18*(1/B18)^(2/3) -> 198.57839 | E18: PCSA | F18: https://anatomypubs.onlinelibrary.wiley.com/doi/10.1002/ar.22518 | G18: =LN(B18) -> 2.4501427 | H18: =LN(C18) -> 6.9246124 | I18: =C18/EXP(0.9087*LN(B18)+4.3479) -> 1.4194476
A19: Lynx rufus | B19: 15.5 | C19: 704.9 | D19: =C19*(1/B19)^(2/3) -> 113.38955 | E19: PCSA | F19: https://anatomypubs.onlinelibrary.wiley.com/doi/10.1002/ar.22518 | G19: =LN(B19) -> 2.74084 | H19: =LN(C19) -> 6.5580559 | I19: =C19/EXP(0.9087*LN(B19)+4.3479) -> 0.7554472
A20: Neofelis nebulosa | B20: 24 | C20: 1613.4 | D20: =C20*(1/B20)^(2/3) -> 193.91045 | E20: PCSA | F20: https://anatomypubs.onlinelibrary.wiley.com/doi/10.1002/ar.22518 | G20: =LN(B20) -> 3.1780538 | H20: =LN(C20) -> 7.386099 | I20: =C20/EXP(0.9087*LN(B20)+4.3479) -> 1.1621846
A21: Panthera onca | B21: 100 | C21: 7057.9 | D21: =C21*(1/B21)^(2/3) -> 327.5987 | E21: PCSA | F21: https://anatomypubs.onlinelibrary.wiley.com/doi/10.1002/ar.22518 | G21: =LN(B21) -> 4.6051702 | H21: =LN(C21) -> 8.8619028 | I21: =C21/EXP(0.9087*LN(B21)+4.3479) -> 1.3899735
A22: Panthera pardus | B22: 34.1 | C22: 2266.1 | D22: =C22*(1/B22)^(2/3) -> 215.49779 | E22: PCSA | F22: https://anatomypubs.onlinelibrary.wiley.com/doi/10.1002/ar.22518 | G22: =LN(B22) -> 3.5292974 | H22: =LN(C22) -> 7.7258156 | I22: =C22/EXP(0.9087*LN(B22)+4.3479) -> 1.1863045
A23: Panthera uncia | B23: 38.64 | C23: 2057.8 | D23: =C23*(1/B23)^(2/3) -> 180.0439 | E23: PCSA | F23: https://anatomypubs.onlinelibrary.wiley.com/doi/10.1002/ar.22518 | G23: =LN(B23) -> 3.654288 | H23: =LN(C23) -> 7.6293927 | I23: =C23/EXP(0.9087*LN(B23)+4.3479) -> 0.96159801
A24: Panthera tigris | B24: 200 | C24: 9101.2 | D24: =C24*(1/B24)^(2/3) -> 266.1207 | E24: PCSA | F24: https://anatomypubs.onlinelibrary.wiley.com/doi/10.1002/ar.22518 | G24: =LN(B24) -> 5.2983174 | H24: =LN(C24) -> 9.1161616 | I24: =C24/EXP(0.9087*LN(B24)+4.3479) -> 0.95473693
A25: Panthera leo | B25: 203 | C25: 7505 | D25: =C25*(1/B25)^(2/3) -> 217.28013 | E25: Corrected dry skull | F25: https://journals.biologists.com/jeb/article/219/23/3738/16607/Accuracy-of-mandibular-force-profiles-for-bite | G25: =LN(B25) -> 5.313206 | H25: =LN(C25) -> 8.9233247 | I25: =C25/EXP(0.9087*LN(B25)+4.3479) -> 0.7767121
A26: Felis catus | B26: 2.57 | C26: 171.9 | D26: =C26*(1/B26)^(2/3) -> 91.619333 | E26: Corrected dry skull | F26: https://doi.org/10.3390/ani10040707 | G26: =LN(B26) -> 0.9439059 | H26: =LN(C26) -> 5.1469129 | I26: =C26/EXP(0.9087*LN(B26)+4.3479) -> 0.94297607
A27: Felis catus | B27: 3.5 | C27: 206.2 | D27: =C27*(1/B27)^(2/3) -> 89.449235 | E27: Corrected dry skull | F27: https://doi.org/10.3390/ani10040707 | G27: =LN(B27) -> 1.252763 | H27: =LN(C27) -> 5.3288466 | I27: =C27/EXP(0.9087*LN(B27)+4.3479) -> 0.85432881
A28: Puma concolor | B28: 39.8 | C28: =773.2*2.2 -> 1701.04 | D28: =C28*(1/B28)^(2/3) -> 145.92369 | E28: Corrected dry skull | F28: https://doi.org/10.1890/0012-9658(2007)88[347:bfaeat]2.0.co;2 and https://journals.biologists.com/jeb/article/219/23/3738/16607/Accuracy-of-mandibular-force-profiles-for-bite | G28: =LN(B28) -> 3.6838669 | H28: =LN(C28) -> 7.4389951 | I28: =C28/EXP(0.9087*LN(B28)+4.3479) -> 0.77380548
A29: Acinonyx jubatus | B29: 47 | C29: =718.9455775*2.2 -> 1581.6803 | D29: =C29*(1/B29)^(2/3) -> 121.447 | E29: Corrected dry skull | F29: https://centaur.reading.ac.uk/117240/2/Palaeontology%20-%202021%20-%20Sakamoto%20-%20Assessing%20bite%20force%20estimates%20in%20extinct%20mammals%20and%20archosaurs%20using%20phylogenetic.pdf | G29: =LN(B29) -> 3.8501476 | H29: =LN(C29) -> 7.366243 | I29: =C29/EXP(0.9087*LN(B29)+4.3479) -> 0.61860638
A30: Smilodon fatalis | B30: 229 | C30: =1104*(1933/976)*2.2 -> 4810.318 | D30: =C30*(1/B30)^(2/3) -> 128.51391 | E30: Corrected dry skull | F30: https://www.pnas.org/doi/10.1073/pnas.0706086104 | G30: =LN(B30) -> 5.433722 | H30: =LN(C30) -> 8.4785185 | I30: =C30/EXP(0.9087*LN(B30)+4.3479) -> 0.44619255
A31: Canids and hyaenids
A32: Canis l. familiaris (Australian Shepherd-Blue Heeler cross) | B32: 15 | C32: 1310 | D32: =C32*(1/B32)^(2/3) -> 215.38252 | E32: In vivo | F32: https://onlinelibrary.wiley.com/doi/10.1111/j.1469-7580.2008.00911.x | G32: =LN(B32) -> 2.7080502 | H32: =LN(C32) -> 7.1777824 | I32: =C32/EXP(0.889*LN(B32)+4.777) -> 0.99334801
A33: Canis l. familiaris (Black Labrador) | B33: 30 | C33: 732 | D33: =C33*(1/B33)^(2/3) -> 75.816473 | E33: In vivo | F33: https://onlinelibrary.wiley.com/doi/10.1111/j.1469-7580.2008.00911.x | G33: =LN(B33) -> 3.4011974 | H33: =LN(C33) -> 6.5957805 | I33: =C33/EXP(0.889*LN(B33)+4.777) -> 0.29972678
A34: Canis l. familiaris (Shar Pe cross) | B34: 19 | C34: 1353 | D34: =C34*(1/B34)^(2/3) -> 190.01829 | E34: In vivo | F34: https://onlinelibrary.wiley.com/doi/10.1111/j.1469-7580.2008.00911.x | G34: =LN(B34) -> 2.944439 | H34: =LN(C34) -> 7.2100796 | I34: =C34/EXP(0.889*LN(B34)+4.777) -> 0.8314978
A35: Canis l. familiaris (Shepherd-Collie crosss) | B35: 18.5 | C35: 2035 | D35: =C35*(1/B35)^(2/3) -> 290.92649 | E35: In vivo | F35: https://onlinelibrary.wiley.com/doi/10.1111/j.1469-7580.2008.00911.x | G35: =LN(B35) -> 2.9177707 | H35: =LN(C35) -> 7.6182511 | I35: =C35/EXP(0.889*LN(B35)+4.777) -> 1.280631
A36: Canis l. familiaris (Spaniel cross) | B36: 11.5 | C36: 573 | D36: =C36*(1/B36)^(2/3) -> 112.46638 | E36: In vivo | F36: https://onlinelibrary.wiley.com/doi/10.1111/j.1469-7580.2008.00911.x | G36: =LN(B36) -> 2.442347 | H36: =LN(C36) -> 6.3508857 | I36: =C36/EXP(0.889*LN(B36)+4.777) -> 0.55026197
A37: Canis l. familiaris ( Jack Russell cross) | B37: 8 | C37: 1025 | D37: =C37*(1/B37)^(2/3) -> 256.25 | E37: In vivo | F37: https://onlinelibrary.wiley.com/doi/10.1111/j.1469-7580.2008.00911.x | G37: =LN(B37) -> 2.0794415 | H37: =LN(C37) -> 6.9324479 | I37: =C37/EXP(0.889*LN(B37)+4.777) -> 1.3591022
A38: Canis l. familiaris (Husky crosss) | B38: 21.5 | C38: 2174 | D38: =C38*(1/B38)^(2/3) -> 281.16887 | E38: In vivo | F38: https://onlinelibrary.wiley.com/doi/10.1111/j.1469-7580.2008.00911.x | G38: =LN(B38) -> 3.0680529 | H38: =LN(C38) -> 7.6843241 | I38: =C38/EXP(0.889*LN(B38)+4.777) -> 1.1970079
A39: Canis l. familiaris (Terrier-Collie cross) | B39: 15.5 | C39: 1890 | D39: =C39*(1/B39)^(2/3) -> 304.02363 | E39: In vivo | F39: https://onlinelibrary.wiley.com/doi/10.1111/j.1469-7580.2008.00911.x | G39: =LN(B39) -> 2.74084 | H39: =LN(C39) -> 7.5443321 | I39: =C39/EXP(0.889*LN(B39)+4.777) -> 1.3919774
A40: Canis l. familiaris (Shepherd cross) | B40: 23.5 | C40: 2202 | D40: =C40*(1/B40)^(2/3) -> 268.39355 | E40: In vivo | F40: https://onlinelibrary.wiley.com/doi/10.1111/j.1469-7580.2008.00911.x | G40: =LN(B40) -> 3.1570004 | H40: =LN(C40) -> 7.6971213 | I40: =C40/EXP(0.889*LN(B40)+4.777) -> 1.1202456
...

Sheet TeethAdjusters
A1: Species | B1: Teeth size adjuster
A2: ='[1]Base stats'!$B2 -> Ursus maritimus | B2: {=IF( SUMPRODUCT(--( TRIM(LEFT(Teeth!$A:$A,SEARCH("§",SUBSTITUTE(Teeth!$A:$A," ","§",2)&"§")-1))= TRIM(LEFT(A2,SEARCH("§",SUBSTITUTE(A2," ","§",2)&"§")-1)) ))>0, IF( COUNT(_xlfn._xlws.FILTER(Teeth!$D:$D, TRIM(LEFT(Teeth!$A:$A,SEARCH("§",SUBSTITUTE(Teeth!$A:$A," ","§",2)&"§")-1))= TRIM(LEFT(A2,SEARCH("§",SUBSTITUTE(A2," ","§",2)&"§")-1)) ))=0, 1, MAX(_xlfn._xlws.FILTER(Teeth!$D:$D, TRIM(LEFT(Teeth!$A:$A,SEARCH("§",SUBSTITUTE(Teeth!$A:$A," ","§",2)&"§")-1))= TRIM(LEFT(A2,SEARCH("§",SUBSTITUTE(A2," ","§",2)&"§")-1)) )) ), IF( SUMPRODUCT(--( TRIM(LEFT(Teeth!$A:$A,SEARCH(" ",Teeth!$A:$A&" ")-1))= TRIM(LEFT(A2,SEARCH(" ",A2&" ")-1)) ))>0, IF( COUNT(_xlfn._xlws.FILTER(Teeth!$D:$D, TRIM(LEFT(Teeth!$A:$A,SEARCH(" ",Teeth!$A:$A&" ")-1))= TRIM(LEFT(A2,SEARCH(" ",A2&" ")-1)) ))=0, 1, AVERAGE(_xlfn._xlws.FILTER(Teeth!$D:$D, TRIM(LEFT(Teeth!$A:$A,SEARCH(" ",Teeth!$A:$A&" ")-1))= TRIM(LEFT(A2,SEARCH(" ",A2&" ")-1)) )) ), 1 ) )} -> 0.83672459
A3: ='[1]Base stats'!$B3 -> Ursus arctos | B3: {=IF( SUMPRODUCT(--( TRIM(LEFT(Teeth!$A:$A,SEARCH("§",SUBSTITUTE(Teeth!$A:$A," ","§",2)&"§")-1))= TRIM(LEFT(A3,SEARCH("§",SUBSTITUTE(A3," ","§",2)&"§")-1)) ))>0, IF( COUNT(_xlfn._xlws.FILTER(Teeth!$D:$D, TRIM(LEFT(Teeth!$A:$A,SEARCH("§",SUBSTITUTE(Teeth!$A:$A," ","§",2)&"§")-1))= TRIM(LEFT(A3,SEARCH("§",SUBSTITUTE(A3," ","§",2)&"§")-1)) ))=0, 1, MAX(_xlfn._xlws.FILTER(Teeth!$D:$D, TRIM(LEFT(Teeth!$A:$A,SEARCH("§",SUBSTITUTE(Teeth!$A:$A," ","§",2)&"§")-1))= TRIM(LEFT(A3,SEARCH("§",SUBSTITUTE(A3," ","§",2)&"§")-1)) )) ), IF( SUMPRODUCT(--( TRIM(LEFT(Teeth!$A:$A,SEARCH(" ",Teeth!$A:$A&" ")-1))= TRIM(LEFT(A3,SEARCH(" ",A3&" ")-1)) ))>0, IF( COUNT(_xlfn._xlws.FILTER(Teeth!$D:$D, TRIM(LEFT(Teeth!$A:$A,SEARCH(" ",Teeth!$A:$A&" ")-1))= TRIM(LEFT(A3,SEARCH(" ",A3&" ")-1)) ))=0, 1, AVERAGE(_xlfn._xlws.FILTER(Teeth!$D:$D, TRIM(LEFT(Teeth!$A:$A,SEARCH(" ",Teeth!$A:$A&" ")-1))= TRIM(LEFT(A3,SEARCH(" ",A3&" ")-1)) )) ), 1 ) )} -> 0.79656343
A4: ='[1]Base stats'!$B4 -> Procyon lotor | B4: {=IF( SUMPRODUCT(--( TRIM(LEFT(Teeth!$A:$A,SEARCH("§",SUBSTITUTE(Teeth!$A:$A," ","§",2)&"§")-1))= TRIM(LEFT(A4,SEARCH("§",SUBSTITUTE(A4," ","§",2)&"§")-1)) ))>0, IF( COUNT(_xlfn._xlws.FILTER(Teeth!$D:$D, TRIM(LEFT(Teeth!$A:$A,SEARCH("§",SUBSTITUTE(Teeth!$A:$A," ","§",2)&"§")-1))= TRIM(LEFT(A4,SEARCH("§",SUBSTITUTE(A4," ","§",2)&"§")-1)) ))=0, 1, MAX(_xlfn._xlws.FILTER(Teeth!$D:$D, TRIM(LEFT(Teeth!$A:$A,SEARCH("§",SUBSTITUTE(Teeth!$A:$A," ","§",2)&"§")-1))= TRIM(LEFT(A4,SEARCH("§",SUBSTITUTE(A4," ","§",2)&"§")-1)) )) ), IF( SUMPRODUCT(--( TRIM(LEFT(Teeth!$A:$A,SEARCH(" ",Teeth!$A:$A&" ")-1))= TRIM(LEFT(A4,SEARCH(" ",A4&" ")-1)) ))>0, IF( COUNT(_xlfn._xlws.FILTER(Teeth!$D:$D, TRIM(LEFT(Teeth!$A:$A,SEARCH(" ",Teeth!$A:$A&" ")-1))= TRIM(LEFT(A4,SEARCH(" ",A4&" ")-1)) ))=0, 1, AVERAGE(_xlfn._xlws.FILTER(Teeth!$D:$D, TRIM(LEFT(Teeth!$A:$A,SEARCH(" ",Teeth!$A:$A&" ")-1))= TRIM(LEFT(A4,SEARCH(" ",A4&" ")-1)) )) ), 1 ) )} -> 1.1605025
A5: ='[1]Base stats'!$B5 -> Struthio camelus | B5: {=IF( SUMPRODUCT(--( TRIM(LEFT(Teeth!$A:$A,SEARCH("§",SUBSTITUTE(Teeth!$A:$A," ","§",2)&"§")-1))= TRIM(LEFT(A5,SEARCH("§",SUBSTITUTE(A5," ","§",2)&"§")-1)) ))>0, IF( COUNT(_xlfn._xlws.FILTER(Teeth!$D:$D, TRIM(LEFT(Teeth!$A:$A,SEARCH("§",SUBSTITUTE(Teeth!$A:$A," ","§",2)&"§")-1))= TRIM(LEFT(A5,SEARCH("§",SUBSTITUTE(A5," ","§",2)&"§")-1)) ))=0, 1, MAX(_xlfn._xlws.FILTER(Teeth!$D:$D, TRIM(LEFT(Teeth!$A:$A,SEARCH("§",SUBSTITUTE(Teeth!$A:$A," ","§",2)&"§")-1))= TRIM(LEFT(A5,SEARCH("§",SUBSTITUTE(A5," ","§",2)&"§")-1)) )) ), IF( SUMPRODUCT(--( TRIM(LEFT(Teeth!$A:$A,SEARCH(" ",Teeth!$A:$A&" ")-1))= TRIM(LEFT(A5,SEARCH(" ",A5&" ")-1)) ))>0, IF( COUNT(_xlfn._xlws.FILTER(Teeth!$D:$D, TRIM(LEFT(Teeth!$A:$A,SEARCH(" ",Teeth!$A:$A&" ")-1))= TRIM(LEFT(A5,SEARCH(" ",A5&" ")-1)) ))=0, 1, AVERAGE(_xlfn._xlws.FILTER(Teeth!$D:$D, TRIM(LEFT(Teeth!$A:$A,SEARCH(" ",Teeth!$A:$A&" ")-1))= TRIM(LEFT(A5,SEARCH(" ",A5&" ")-1)) )) ), 1 ) )} -> 1
A6: ='[1]Base stats'!$B6 -> Casuarius casuarius | B6: {=IF( SUMPRODUCT(--( TRIM(LEFT(Teeth!$A:$A,SEARCH("§",SUBSTITUTE(Teeth!$A:$A," ","§",2)&"§")-1))= TRIM(LEFT(A6,SEARCH("§",SUBSTITUTE(A6," ","§",2)&"§")-1)) ))>0, IF( COUNT(_xlfn._xlws.FILTER(Teeth!$D:$D, TRIM(LEFT(Teeth!$A:$A,SEARCH("§",SUBSTITUTE(Teeth!$A:$A," ","§",2)&"§")-1))= TRIM(LEFT(A6,SEARCH("§",SUBSTITUTE(A6," ","§",2)&"§")-1)) ))=0, 1, MAX(_xlfn._xlws.FILTER(Teeth!$D:$D, TRIM(LEFT(Teeth!$A:$A,SEARCH("§",SUBSTITUTE(Teeth!$A:$A," ","§",2)&"§")-1))= TRIM(LEFT(A6,SEARCH("§",SUBSTITUTE(A6," ","§",2)&"§")-1)) )) ), IF( SUMPRODUCT(--( TRIM(LEFT(Teeth!$A:$A,SEARCH(" ",Teeth!$A:$A&" ")-1))= TRIM(LEFT(A6,SEARCH(" ",A6&" ")-1)) ))>0, IF( COUNT(_xlfn._xlws.FILTER(Teeth!$D:$D, TRIM(LEFT(Teeth!$A:$A,SEARCH(" ",Teeth!$A:$A&" ")-1))= TRIM(LEFT(A6,SEARCH(" ",A6&" ")-1)) ))=0, 1, AVERAGE(_xlfn._xlws.FILTER(Teeth!$D:$D, TRIM(LEFT(Teeth!$A:$A,SEARCH(" ",Teeth!$A:$A&" ")-1))= TRIM(LEFT(A6,SEARCH(" ",A6&" ")-1)) )) ), 1 ) )} -> 1
A7: ='[1]Base stats'!$B7 -> Dromaius novaehollandiae | B7: {=IF( SUMPRODUCT(--( TRIM(LEFT(Teeth!$A:$A,SEARCH("§",SUBSTITUTE(Teeth!$A:$A," ","§",2)&"§")-1))= TRIM(LEFT(A7,SEARCH("§",SUBSTITUTE(A7," ","§",2)&"§")-1)) ))>0, IF( COUNT(_xlfn._xlws.FILTER(Teeth!$D:$D, TRIM(LEFT(Teeth!$A:$A,SEARCH("§",SUBSTITUTE(Teeth!$A:$A," ","§",2)&"§")-1))= TRIM(LEFT(A7,SEARCH("§",SUBSTITUTE(A7," ","§",2)&"§")-1)) ))=0, 1, MAX(_xlfn._xlws.FILTER(Teeth!$D:$D, TRIM(LEFT(Teeth!$A:$A,SEARCH("§",SUBSTITUTE(Teeth!$A:$A," ","§",2)&"§")-1))= TRIM(LEFT(A7,SEARCH("§",SUBSTITUTE(A7," ","§",2)&"§")-1)) )) ), IF( SUMPRODUCT(--( TRIM(LEFT(Teeth!$A:$A,SEARCH(" ",Teeth!$A:$A&" ")-1))= TRIM(LEFT(A7,SEARCH(" ",A7&" ")-1)) ))>0, IF( COUNT(_xlfn._xlws.FILTER(Teeth!$D:$D, TRIM(LEFT(Teeth!$A:$A,SEARCH(" ",Teeth!$A:$A&" ")-1))= TRIM(LEFT(A7,SEARCH(" ",A7&" ")-1)) ))=0, 1, AVERAGE(_xlfn._xlws.FILTER(Teeth!$D:$D, TRIM(LEFT(Teeth!$A:$A,SEARCH(" ",Teeth!$A:$A&" ")-1))= TRIM(LEFT(A7,SEARCH(" ",A7&" ")-1)) )) ), 1 ) )} -> 1
A8: ='[1]Base stats'!$B8 -> Meleagris gallopavo (wild) | B8: {=IF( SUMPRODUCT(--( TRIM(LEFT(Teeth!$A:$A,SEARCH("§",SUBSTITUTE(Teeth!$A:$A," ","§",2)&"§")-1))= TRIM(LEFT(A8,SEARCH("§",SUBSTITUTE(A8," ","§",2)&"§")-1)) ))>0, IF( COUNT(_xlfn._xlws.FILTER(Teeth!$D:$D, TRIM(LEFT(Teeth!$A:$A,SEARCH("§",SUBSTITUTE(Teeth!$A:$A," ","§",2)&"§")-1))= TRIM(LEFT(A8,SEARCH("§",SUBSTITUTE(A8," ","§",2)&"§")-1)) ))=0, 1, MAX(_xlfn._xlws.FILTER(Teeth!$D:$D, TRIM(LEFT(Teeth!$A:$A,SEARCH("§",SUBSTITUTE(Teeth!$A:$A," ","§",2)&"§")-1))= TRIM(LEFT(A8,SEARCH("§",SUBSTITUTE(A8," ","§",2)&"§")-1)) )) ), IF( SUMPRODUCT(--( TRIM(LEFT(Teeth!$A:$A,SEARCH(" ",Teeth!$A:$A&" ")-1))= TRIM(LEFT(A8,SEARCH(" ",A8&" ")-1)) ))>0, IF( COUNT(_xlfn._xlws.FILTER(Teeth!$D:$D, TRIM(LEFT(Teeth!$A:$A,SEARCH(" ",Teeth!$A:$A&" ")-1))= TRIM(LEFT(A8,SEARCH(" ",A8&" ")-1)) ))=0, 1, AVERAGE(_xlfn._xlws.FILTER(Teeth!$D:$D, TRIM(LEFT(Teeth!$A:$A,SEARCH(" ",Teeth!$A:$A&" ")-1))= TRIM(LEFT(A8,SEARCH(" ",A8&" ")-1)) )) ), 1 ) )} -> 1
A9: ='[1]Base stats'!$B9 -> Anser anser (Adler) | B9: {=IF( SUMPRODUCT(--( TRIM(LEFT(Teeth!$A:$A,SEARCH("§",SUBSTITUTE(Teeth!$A:$A," ","§",2)&"§")-1))= TRIM(LEFT(A9,SEARCH("§",SUBSTITUTE(A9," ","§",2)&"§")-1)) ))>0, IF( COUNT(_xlfn._xlws.FILTER(Teeth!$D:$D, TRIM(LEFT(Teeth!$A:$A,SEARCH("§",SUBSTITUTE(Teeth!$A:$A," ","§",2)&"§")-1))= TRIM(LEFT(A9,SEARCH("§",SUBSTITUTE(A9," ","§",2)&"§")-1)) ))=0, 1, MAX(_xlfn._xlws.FILTER(Teeth!$D:$D, TRIM(LEFT(Teeth!$A:$A,SEARCH("§",SUBSTITUTE(Teeth!$A:$A," ","§",2)&"§")-1))= TRIM(LEFT(A9,SEARCH("§",SUBSTITUTE(A9," ","§",2)&"§")-1)) )) ), IF( SUMPRODUCT(--( TRIM(LEFT(Teeth!$A:$A,SEARCH(" ",Teeth!$A:$A&" ")-1))= TRIM(LEFT(A9,SEARCH(" ",A9&" ")-1)) ))>0, IF( COUNT(_xlfn._xlws.FILTER(Teeth!$D:$D, TRIM(LEFT(Teeth!$A:$A,SEARCH(" ",Teeth!$A:$A&" ")-1))= TRIM(LEFT(A9,SEARCH(" ",A9&" ")-1)) ))=0, 1, AVERAGE(_xlfn._xlws.FILTER(Teeth!$D:$D, TRIM(LEFT(Teeth!$A:$A,SEARCH(" ",Teeth!$A:$A&" ")-1))= TRIM(LEFT(A9,SEARCH(" ",A9&" ")-1)) )) ), 1 ) )} -> 1
A10: ='[1]Base stats'!$B10 -> Anas platyrhynchos (wild) | B10: {=IF( SUMPRODUCT(--( TRIM(LEFT(Teeth!$A:$A,SEARCH("§",SUBSTITUTE(Teeth!$A:$A," ","§",2)&"§")-1))= TRIM(LEFT(A10,SEARCH("§",SUBSTITUTE(A10," ","§",2)&"§")-1)) ))>0, IF( COUNT(_xlfn._xlws.FILTER(Teeth!$D:$D, TRIM(LEFT(Teeth!$A:$A,SEARCH("§",SUBSTITUTE(Teeth!$A:$A," ","§",2)&"§")-1))= TRIM(LEFT(A10,SEARCH("§",SUBSTITUTE(A10," ","§",2)&"§")-1)) ))=0, 1, MAX(_xlfn._xlws.FILTER(Teeth!$D:$D, TRIM(LEFT(Teeth!$A:$A,SEARCH("§",SUBSTITUTE(Teeth!$A:$A," ","§",2)&"§")-1))= TRIM(LEFT(A10,SEARCH("§",SUBSTITUTE(A10," ","§",2)&"§")-1)) )) ), IF( SUMPRODUCT(--( TRIM(LEFT(Teeth!$A:$A,SEARCH(" ",Teeth!$A:$A&" ")-1))= TRIM(LEFT(A10,SEARCH(" ",A10&" ")-1)) ))>0, IF( COUNT(_xlfn._xlws.FILTER(Teeth!$D:$D, TRIM(LEFT(Teeth!$A:$A,SEARCH(" ",Teeth!$A:$A&" ")-1))= TRIM(LEFT(A10,SEARCH(" ",A10&" ")-1)) ))=0, 1, AVERAGE(_xlfn._xlws.FILTER(Teeth!$D:$D, TRIM(LEFT(Teeth!$A:$A,SEARCH(" ",Teeth!$A:$A&" ")-1))= TRIM(LEFT(A10,SEARCH(" ",A10&" ")-1)) )) ), 1 ) )} -> 1
A11: ='[1]Base stats'!$B11 -> Gallus gallus | B11: {=IF( SUMPRODUCT(--( TRIM(LEFT(Teeth!$A:$A,SEARCH("§",SUBSTITUTE(Teeth!$A:$A," ","§",2)&"§")-1))= TRIM(LEFT(A11,SEARCH("§",SUBSTITUTE(A11," ","§",2)&"§")-1)) ))>0, IF( COUNT(_xlfn._xlws.FILTER(Teeth!$D:$D, TRIM(LEFT(Teeth!$A:$A,SEARCH("§",SUBSTITUTE(Teeth!$A:$A," ","§",2)&"§")-1))= TRIM(LEFT(A11,SEARCH("§",SUBSTITUTE(A11," ","§",2)&"§")-1)) ))=0, 1, MAX(_xlfn._xlws.FILTER(Teeth!$D:$D, TRIM(LEFT(Teeth!$A:$A,SEARCH("§",SUBSTITUTE(Teeth!$A:$A," ","§",2)&"§")-1))= TRIM(LEFT(A11,SEARCH("§",SUBSTITUTE(A11," ","§",2)&"§")-1)) )) ), IF( SUMPRODUCT(--( TRIM(LEFT(Teeth!$A:$A,SEARCH(" ",Teeth!$A:$A&" ")-1))= TRIM(LEFT(A11,SEARCH(" ",A11&" ")-1)) ))>0, IF( COUNT(_xlfn._xlws.FILTER(Teeth!$D:$D, TRIM(LEFT(Teeth!$A:$A,SEARCH(" ",Teeth!$A:$A&" ")-1))= TRIM(LEFT(A11,SEARCH(" ",A11&" ")-1)) ))=0, 1, AVERAGE(_xlfn._xlws.FILTER(Teeth!$D:$D, TRIM(LEFT(Teeth!$A:$A,SEARCH(" ",Teeth!$A:$A&" ")-1))= TRIM(LEFT(A11,SEARCH(" ",A11&" ")-1)) )) ), 1 ) )} -> 1
A12: ='[1]Base stats'!$B12 -> Camelus dromedarius | B12: {=IF( SUMPRODUCT(--( TRIM(LEFT(Teeth!$A:$A,SEARCH("§",SUBSTITUTE(Teeth!$A:$A," ","§",2)&"§")-1))= TRIM(LEFT(A12,SEARCH("§",SUBSTITUTE(A12," ","§",2)&"§")-1)) ))>0, IF( COUNT(_xlfn._xlws.FILTER(Teeth!$D:$D, TRIM(LEFT(Teeth!$A:$A,SEARCH("§",SUBSTITUTE(Teeth!$A:$A," ","§",2)&"§")-1))= TRIM(LEFT(A12,SEARCH("§",SUBSTITUTE(A12," ","§",2)&"§")-1)) ))=0, 1, MAX(_xlfn._xlws.FILTER(Teeth!$D:$D, TRIM(LEFT(Teeth!$A:$A,SEARCH("§",SUBSTITUTE(Teeth!$A:$A," ","§",2)&"§")-1))= TRIM(LEFT(A12,SEARCH("§",SUBSTITUTE(A12," ","§",2)&"§")-1)) )) ), IF( SUMPRODUCT(--( TRIM(LEFT(Teeth!$A:$A,SEARCH(" ",Teeth!$A:$A&" ")-1))= TRIM(LEFT(A12,SEARCH(" ",A12&" ")-1)) ))>0, IF( COUNT(_xlfn._xlws.FILTER(Teeth!$D:$D, TRIM(LEFT(Teeth!$A:$A,SEARCH(" ",Teeth!$A:$A&" ")-1))= TRIM(LEFT(A12,SEARCH(" ",A12&" ")-1)) ))=0, 1, AVERAGE(_xlfn._xlws.FILTER(Teeth!$D:$D, TRIM(LEFT(Teeth!$A:$A,SEARCH(" ",Teeth!$A:$A&" ")-1))= TRIM(LEFT(A12,SEARCH(" ",A12&" ")-1)) )) ), 1 ) )} -> 1
A13: ='[1]Base stats'!$B13 -> Lama pacos | B13: {=IF( SUMPRODUCT(--( TRIM(LEFT(Teeth!$A:$A,SEARCH("§",SUBSTITUTE(Teeth!$A:$A," ","§",2)&"§")-1))= TRIM(LEFT(A13,SEARCH("§",SUBSTITUTE(A13," ","§",2)&"§")-1)) ))>0, IF( COUNT(_xlfn._xlws.FILTER(Teeth!$D:$D, TRIM(LEFT(Teeth!$A:$A,SEARCH("§",SUBSTITUTE(Teeth!$A:$A," ","§",2)&"§")-1))= TRIM(LEFT(A13,SEARCH("§",SUBSTITUTE(A13," ","§",2)&"§")-1)) ))=0, 1, MAX(_xlfn._xlws.FILTER(Teeth!$D:$D, TRIM(LEFT(Teeth!$A:$A,SEARCH("§",SUBSTITUTE(Teeth!$A:$A," ","§",2)&"§")-1))= TRIM(LEFT(A13,SEARCH("§",SUBSTITUTE(A13," ","§",2)&"§")-1)) )) ), IF( SUMPRODUCT(--( TRIM(LEFT(Teeth!$A:$A,SEARCH(" ",Teeth!$A:$A&" ")-1))= TRIM(LEFT(A13,SEARCH(" ",A13&" ")-1)) ))>0, IF( COUNT(_xlfn._xlws.FILTER(Teeth!$D:$D, TRIM(LEFT(Teeth!$A:$A,SEARCH(" ",Teeth!$A:$A&" ")-1))= TRIM(LEFT(A13,SEARCH(" ",A13&" ")-1)) ))=0, 1, AVERAGE(_xlfn._xlws.FILTER(Teeth!$D:$D, TRIM(LEFT(Teeth!$A:$A,SEARCH(" ",Teeth!$A:$A&" ")-1))= TRIM(LEFT(A13,SEARCH(" ",A13&" ")-1)) )) ), 1 ) )} -> 1
... A361: ='[1]Base stats'!$B361 -> Pteranodon longiceps | B361: {=IF( SUMPRODUCT(--( TRIM(LEFT(Teeth!$A:$A,SEARCH("§",SUBSTITUTE(Teeth!$A:$A," ","§",2)&"§")-1))= TRIM(LEFT(A361,SEARCH("§",SUBSTITUTE(A361," ","§",2)&"§")-1)) ))>0, IF( COUNT(_xlfn._xlws.FILTER(Teeth!$D:$D, TRIM(LEFT(Teeth!$A:$A,SEARCH("§",SUBSTITUTE(Teeth!$A:$A," ","§",2)&"§")-1))= TRIM(LEFT(A361,SEARCH("§",SUBSTITUTE(A361," ","§",2)&"§")-1)) ))=0, 1, MAX(_xlfn._xlws.FILTER(Teeth!$D:$D, TRIM(LEFT(Teeth!$A:$A,SEARCH("§",SUBSTITUTE(Teeth!$A:$A," ","§",2)&"§")-1))= TRIM(LEFT(A361,SEARCH("§",SUBSTITUTE(A361," ","§",2)&"§")-1)) )) ), IF( SUMPRODUCT(--( TRIM(LEFT(Teeth!$A:$A,SEARCH(" ",Teeth!$A:$A&" ")-1))= TRIM(LEFT(A361,SEARCH(" ",A361&" ")-1)) ))>0, IF( COUNT(_xlfn._xlws.FILTER(Teeth!$D:$D, TRIM(LEFT(Teeth!$A:$A,SEARCH(" ",Teeth!$A:$A&" ")-1))= TRIM(LEFT(A361,SEARCH(" ",A361&" ")-1)) ))=0, 1, AVERAGE(_xlfn._xlws.FILTER(Teeth!$D:$D, TRIM(LEFT(Teeth!$A:$A,SEARCH(" ",Teeth!$A:$A&" ")-1))= TRIM(LEFT(A361,SEARCH(" ",A361&" ")-1)) )) ), 1 ) )} -> 1

Sheet BiteAdjusters
A1: Species | B1: DomesticationLevel | C1: Bite force adjuster
A2: ='[1]Base stats'!$B2 -> Ursus maritimus | B2: =_xlfn.XLOOKUP(A2,'[1]Base stats'!$B:$B,'[1]Base stats'!$O:$O) -> 0 | C2: {=IF( SUMPRODUCT(--( TRIM(LEFT('Bite force'!$A:$A,SEARCH("§",SUBSTITUTE('Bite force'!$A:$A," ","§",2)&"§")-1))= TRIM(LEFT(A2,SEARCH("§",SUBSTITUTE(A2," ","§",2)&"§")-1)) ))>0, IF( COUNT(_xlfn._xlws.FILTER('Bite force'!$I:$I, TRIM(LEFT('Bite force'!$A:$A,SEARCH("§",SUBSTITUTE('Bite force'!$A:$A," ","§",2)&"§")-1))= TRIM(LEFT(A2,SEARCH("§",SUBSTITUTE(A2," ","§",2)&"§")-1)) ))=0, 1, IF( B2=2, AVERAGE(_xlfn._xlws.FILTER('Bite force'!$I:$I, TRIM(LEFT('Bite force'!$A:$A,SEARCH("§",SUBSTITUTE('Bite force'!$A:$A," ","§",2)&"§")-1))= TRIM(LEFT(A2,SEARCH("§",SUBSTITUTE(A2," ","§",2)&"§")-1)) )), MAX(_xlfn._xlws.FILTER('Bite force'!$I:$I, TRIM(LEFT('Bite force'!$A:$A,SEARCH("§",SUBSTITUTE('Bite force'!$A:$A," ","§",2)&"§")-1))= TRIM(LEFT(A2,SEARCH("§",SUBSTITUTE(A2," ","§",2)&"§")-1)) )) ) ), IFERROR( AVERAGE(_xlfn._xlws.FILTER('Bite force'!$I:$I, TRIM(LEFT('Bite force'!$A:$A,SEARCH(" ",'Bite force'!$A:$A&" ")-1))= TRIM(LEFT(A2,SEARCH(" ",A2&" ")-1)) )), 1 ) )} -> 0.86920397
A3: ='[1]Base stats'!$B3 -> Ursus arctos | B3: =_xlfn.XLOOKUP(A3,'[1]Base stats'!$B:$B,'[1]Base stats'!$O:$O) -> 0 | C3: {=IF( SUMPRODUCT(--( TRIM(LEFT('Bite force'!$A:$A,SEARCH("§",SUBSTITUTE('Bite force'!$A:$A," ","§",2)&"§")-1))= TRIM(LEFT(A3,SEARCH("§",SUBSTITUTE(A3," ","§",2)&"§")-1)) ))>0, IF( COUNT(_xlfn._xlws.FILTER('Bite force'!$I:$I, TRIM(LEFT('Bite force'!$A:$A,SEARCH("§",SUBSTITUTE('Bite force'!$A:$A," ","§",2)&"§")-1))= TRIM(LEFT(A3,SEARCH("§",SUBSTITUTE(A3," ","§",2)&"§")-1)) ))=0, 1, IF( B3=2, AVERAGE(_xlfn._xlws.FILTER('Bite force'!$I:$I, TRIM(LEFT('Bite force'!$A:$A,SEARCH("§",SUBSTITUTE('Bite force'!$A:$A," ","§",2)&"§")-1))= TRIM(LEFT(A3,SEARCH("§",SUBSTITUTE(A3," ","§",2)&"§")-1)) )), MAX(_xlfn._xlws.FILTER('Bite force'!$I:$I, TRIM(LEFT('Bite force'!$A:$A,SEARCH("§",SUBSTITUTE('Bite force'!$A:$A," ","§",2)&"§")-1))= TRIM(LEFT(A3,SEARCH("§",SUBSTITUTE(A3," ","§",2)&"§")-1)) )) ) ), IFERROR( AVERAGE(_xlfn._xlws.FILTER('Bite force'!$I:$I, TRIM(LEFT('Bite force'!$A:$A,SEARCH(" ",'Bite force'!$A:$A&" ")-1))= TRIM(LEFT(A3,SEARCH(" ",A3&" ")-1)) )), 1 ) )} -> 1.0629975
A4: ='[1]Base stats'!$B4 -> Procyon lotor | B4: =_xlfn.XLOOKUP(A4,'[1]Base stats'!$B:$B,'[1]Base stats'!$O:$O) -> 0 | C4: {=IF( SUMPRODUCT(--( TRIM(LEFT('Bite force'!$A:$A,SEARCH("§",SUBSTITUTE('Bite force'!$A:$A," ","§",2)&"§")-1))= TRIM(LEFT(A4,SEARCH("§",SUBSTITUTE(A4," ","§",2)&"§")-1)) ))>0, IF( COUNT(_xlfn._xlws.FILTER('Bite force'!$I:$I, TRIM(LEFT('Bite force'!$A:$A,SEARCH("§",SUBSTITUTE('Bite force'!$A:$A," ","§",2)&"§")-1))= TRIM(LEFT(A4,SEARCH("§",SUBSTITUTE(A4," ","§",2)&"§")-1)) ))=0, 1, IF( B4=2, AVERAGE(_xlfn._xlws.FILTER('Bite force'!$I:$I, TRIM(LEFT('Bite force'!$A:$A,SEARCH("§",SUBSTITUTE('Bite force'!$A:$A," ","§",2)&"§")-1))= TRIM(LEFT(A4,SEARCH("§",SUBSTITUTE(A4," ","§",2)&"§")-1)) )), MAX(_xlfn._xlws.FILTER('Bite force'!$I:$I, TRIM(LEFT('Bite force'!$A:$A,SEARCH("§",SUBSTITUTE('Bite force'!$A:$A," ","§",2)&"§")-1))= TRIM(LEFT(A4,SEARCH("§",SUBSTITUTE(A4," ","§",2)&"§")-1)) )) ) ), IFERROR( AVERAGE(_xlfn._xlws.FILTER('Bite force'!$I:$I, TRIM(LEFT('Bite force'!$A:$A,SEARCH(" ",'Bite force'!$A:$A&" ")-1))= TRIM(LEFT(A4,SEARCH(" ",A4&" ")-1)) )), 1 ) )} -> 0.72645239
A5: ='[1]Base stats'!$B5 -> Struthio camelus | B5: =_xlfn.XLOOKUP(A5,'[1]Base stats'!$B:$B,'[1]Base stats'!$O:$O) -> 0 | C5: {=IF( SUMPRODUCT(--( TRIM(LEFT('Bite force'!$A:$A,SEARCH("§",SUBSTITUTE('Bite force'!$A:$A," ","§",2)&"§")-1))= TRIM(LEFT(A5,SEARCH("§",SUBSTITUTE(A5," ","§",2)&"§")-1)) ))>0, IF( COUNT(_xlfn._xlws.FILTER('Bite force'!$I:$I, TRIM(LEFT('Bite force'!$A:$A,SEARCH("§",SUBSTITUTE('Bite force'!$A:$A," ","§",2)&"§")-1))= TRIM(LEFT(A5,SEARCH("§",SUBSTITUTE(A5," ","§",2)&"§")-1)) ))=0, 1, IF( B5=2, AVERAGE(_xlfn._xlws.FILTER('Bite force'!$I:$I, TRIM(LEFT('Bite force'!$A:$A,SEARCH("§",SUBSTITUTE('Bite force'!$A:$A," ","§",2)&"§")-1))= TRIM(LEFT(A5,SEARCH("§",SUBSTITUTE(A5," ","§",2)&"§")-1)) )), MAX(_xlfn._xlws.FILTER('Bite force'!$I:$I, TRIM(LEFT('Bite force'!$A:$A,SEARCH("§",SUBSTITUTE('Bite force'!$A:$A," ","§",2)&"§")-1))= TRIM(LEFT(A5,SEARCH("§",SUBSTITUTE(A5," ","§",2)&"§")-1)) )) ) ), IFERROR( AVERAGE(_xlfn._xlws.FILTER('Bite force'!$I:$I, TRIM(LEFT('Bite force'!$A:$A,SEARCH(" ",'Bite force'!$A:$A&" ")-1))= TRIM(LEFT(A5,SEARCH(" ",A5&" ")-1)) )), 1 ) )} -> 1
A6: ='[1]Base stats'!$B6 -> Casuarius casuarius | B6: =_xlfn.XLOOKUP(A6,'[1]Base stats'!$B:$B,'[1]Base stats'!$O:$O) -> 0 | C6: {=IF( SUMPRODUCT(--( TRIM(LEFT('Bite force'!$A:$A,SEARCH("§",SUBSTITUTE('Bite force'!$A:$A," ","§",2)&"§")-1))= TRIM(LEFT(A6,SEARCH("§",SUBSTITUTE(A6," ","§",2)&"§")-1)) ))>0, IF( COUNT(_xlfn._xlws.FILTER('Bite force'!$I:$I, TRIM(LEFT('Bite force'!$A:$A,SEARCH("§",SUBSTITUTE('Bite force'!$A:$A," ","§",2)&"§")-1))= TRIM(LEFT(A6,SEARCH("§",SUBSTITUTE(A6," ","§",2)&"§")-1)) ))=0, 1, IF( B6=2, AVERAGE(_xlfn._xlws.FILTER('Bite force'!$I:$I, TRIM(LEFT('Bite force'!$A:$A,SEARCH("§",SUBSTITUTE('Bite force'!$A:$A," ","§",2)&"§")-1))= TRIM(LEFT(A6,SEARCH("§",SUBSTITUTE(A6," ","§",2)&"§")-1)) )), MAX(_xlfn._xlws.FILTER('Bite force'!$I:$I, TRIM(LEFT('Bite force'!$A:$A,SEARCH("§",SUBSTITUTE('Bite force'!$A:$A," ","§",2)&"§")-1))= TRIM(LEFT(A6,SEARCH("§",SUBSTITUTE(A6," ","§",2)&"§")-1)) )) ) ), IFERROR( AVERAGE(_xlfn._xlws.FILTER('Bite force'!$I:$I, TRIM(LEFT('Bite force'!$A:$A,SEARCH(" ",'Bite force'!$A:$A&" ")-1))= TRIM(LEFT(A6,SEARCH(" ",A6&" ")-1)) )), 1 ) )} -> 1
A7: ='[1]Base stats'!$B7 -> Dromaius novaehollandiae | B7: =_xlfn.XLOOKUP(A7,'[1]Base stats'!$B:$B,'[1]Base stats'!$O:$O) -> 0 | C7: {=IF( SUMPRODUCT(--( TRIM(LEFT('Bite force'!$A:$A,SEARCH("§",SUBSTITUTE('Bite force'!$A:$A," ","§",2)&"§")-1))= TRIM(LEFT(A7,SEARCH("§",SUBSTITUTE(A7," ","§",2)&"§")-1)) ))>0, IF( COUNT(_xlfn._xlws.FILTER('Bite force'!$I:$I, TRIM(LEFT('Bite force'!$A:$A,SEARCH("§",SUBSTITUTE('Bite force'!$A:$A," ","§",2)&"§")-1))= TRIM(LEFT(A7,SEARCH("§",SUBSTITUTE(A7," ","§",2)&"§")-1)) ))=0, 1, IF( B7=2, AVERAGE(_xlfn._xlws.FILTER('Bite force'!$I:$I, TRIM(LEFT('Bite force'!$A:$A,SEARCH("§",SUBSTITUTE('Bite force'!$A:$A," ","§",2)&"§")-1))= TRIM(LEFT(A7,SEARCH("§",SUBSTITUTE(A7," ","§",2)&"§")-1)) )), MAX(_xlfn._xlws.FILTER('Bite force'!$I:$I, TRIM(LEFT('Bite force'!$A:$A,SEARCH("§",SUBSTITUTE('Bite force'!$A:$A," ","§",2)&"§")-1))= TRIM(LEFT(A7,SEARCH("§",SUBSTITUTE(A7," ","§",2)&"§")-1)) )) ) ), IFERROR( AVERAGE(_xlfn._xlws.FILTER('Bite force'!$I:$I, TRIM(LEFT('Bite force'!$A:$A,SEARCH(" ",'Bite force'!$A:$A&" ")-1))= TRIM(LEFT(A7,SEARCH(" ",A7&" ")-1)) )), 1 ) )} -> 1
A8: ='[1]Base stats'!$B8 -> Meleagris gallopavo (wild) | B8: =_xlfn.XLOOKUP(A8,'[1]Base stats'!$B:$B,'[1]Base stats'!$O:$O) -> 0 | C8: {=IF( SUMPRODUCT(--( TRIM(LEFT('Bite force'!$A:$A,SEARCH("§",SUBSTITUTE('Bite force'!$A:$A," ","§",2)&"§")-1))= TRIM(LEFT(A8,SEARCH("§",SUBSTITUTE(A8," ","§",2)&"§")-1)) ))>0, IF( COUNT(_xlfn._xlws.FILTER('Bite force'!$I:$I, TRIM(LEFT('Bite force'!$A:$A,SEARCH("§",SUBSTITUTE('Bite force'!$A:$A," ","§",2)&"§")-1))= TRIM(LEFT(A8,SEARCH("§",SUBSTITUTE(A8," ","§",2)&"§")-1)) ))=0, 1, IF( B8=2, AVERAGE(_xlfn._xlws.FILTER('Bite force'!$I:$I, TRIM(LEFT('Bite force'!$A:$A,SEARCH("§",SUBSTITUTE('Bite force'!$A:$A," ","§",2)&"§")-1))= TRIM(LEFT(A8,SEARCH("§",SUBSTITUTE(A8," ","§",2)&"§")-1)) )), MAX(_xlfn._xlws.FILTER('Bite force'!$I:$I, TRIM(LEFT('Bite force'!$A:$A,SEARCH("§",SUBSTITUTE('Bite force'!$A:$A," ","§",2)&"§")-1))= TRIM(LEFT(A8,SEARCH("§",SUBSTITUTE(A8," ","§",2)&"§")-1)) )) ) ), IFERROR( AVERAGE(_xlfn._xlws.FILTER('Bite force'!$I:$I, TRIM(LEFT('Bite force'!$A:$A,SEARCH(" ",'Bite force'!$A:$A&" ")-1))= TRIM(LEFT(A8,SEARCH(" ",A8&" ")-1)) )), 1 ) )} -> 1
A9: ='[1]Base stats'!$B9 -> Anser anser (Adler) | B9: =_xlfn.XLOOKUP(A9,'[1]Base stats'!$B:$B,'[1]Base stats'!$O:$O) -> 2 | C9: {=IF( SUMPRODUCT(--( TRIM(LEFT('Bite force'!$A:$A,SEARCH("§",SUBSTITUTE('Bite force'!$A:$A," ","§",2)&"§")-1))= TRIM(LEFT(A9,SEARCH("§",SUBSTITUTE(A9," ","§",2)&"§")-1)) ))>0, IF( COUNT(_xlfn._xlws.FILTER('Bite force'!$I:$I, TRIM(LEFT('Bite force'!$A:$A,SEARCH("§",SUBSTITUTE('Bite force'!$A:$A," ","§",2)&"§")-1))= TRIM(LEFT(A9,SEARCH("§",SUBSTITUTE(A9," ","§",2)&"§")-1)) ))=0, 1, IF( B9=2, AVERAGE(_xlfn._xlws.FILTER('Bite force'!$I:$I, TRIM(LEFT('Bite force'!$A:$A,SEARCH("§",SUBSTITUTE('Bite force'!$A:$A," ","§",2)&"§")-1))= TRIM(LEFT(A9,SEARCH("§",SUBSTITUTE(A9," ","§",2)&"§")-1)) )), MAX(_xlfn._xlws.FILTER('Bite force'!$I:$I, TRIM(LEFT('Bite force'!$A:$A,SEARCH("§",SUBSTITUTE('Bite force'!$A:$A," ","§",2)&"§")-1))= TRIM(LEFT(A9,SEARCH("§",SUBSTITUTE(A9," ","§",2)&"§")-1)) )) ) ), IFERROR( AVERAGE(_xlfn._xlws.FILTER('Bite force'!$I:$I, TRIM(LEFT('Bite force'!$A:$A,SEARCH(" ",'Bite force'!$A:$A&" ")-1))= TRIM(LEFT(A9,SEARCH(" ",A9&" ")-1)) )), 1 ) )} -> 1
A10: ='[1]Base stats'!$B10 -> Anas platyrhynchos (wild) | B10: =_xlfn.XLOOKUP(A10,'[1]Base stats'!$B:$B,'[1]Base stats'!$O:$O) -> 0 | C10: {=IF( SUMPRODUCT(--( TRIM(LEFT('Bite force'!$A:$A,SEARCH("§",SUBSTITUTE('Bite force'!$A:$A," ","§",2)&"§")-1))= TRIM(LEFT(A10,SEARCH("§",SUBSTITUTE(A10," ","§",2)&"§")-1)) ))>0, IF( COUNT(_xlfn._xlws.FILTER('Bite force'!$I:$I, TRIM(LEFT('Bite force'!$A:$A,SEARCH("§",SUBSTITUTE('Bite force'!$A:$A," ","§",2)&"§")-1))= TRIM(LEFT(A10,SEARCH("§",SUBSTITUTE(A10," ","§",2)&"§")-1)) ))=0, 1, IF( B10=2, AVERAGE(_xlfn._xlws.FILTER('Bite force'!$I:$I, TRIM(LEFT('Bite force'!$A:$A,SEARCH("§",SUBSTITUTE('Bite force'!$A:$A," ","§",2)&"§")-1))= TRIM(LEFT(A10,SEARCH("§",SUBSTITUTE(A10," ","§",2)&"§")-1)) )), MAX(_xlfn._xlws.FILTER('Bite force'!$I:$I, TRIM(LEFT('Bite force'!$A:$A,SEARCH("§",SUBSTITUTE('Bite force'!$A:$A," ","§",2)&"§")-1))= TRIM(LEFT(A10,SEARCH("§",SUBSTITUTE(A10," ","§",2)&"§")-1)) )) ) ), IFERROR( AVERAGE(_xlfn._xlws.FILTER('Bite force'!$I:$I, TRIM(LEFT('Bite force'!$A:$A,SEARCH(" ",'Bite force'!$A:$A&" ")-1))= TRIM(LEFT(A10,SEARCH(" ",A10&" ")-1)) )), 1 ) )} -> 1
A11: ='[1]Base stats'!$B11 -> Gallus gallus | B11: =_xlfn.XLOOKUP(A11,'[1]Base stats'!$B:$B,'[1]Base stats'!$O:$O) -> 2 | C11: {=IF( SUMPRODUCT(--( TRIM(LEFT('Bite force'!$A:$A,SEARCH("§",SUBSTITUTE('Bite force'!$A:$A," ","§",2)&"§")-1))= TRIM(LEFT(A11,SEARCH("§",SUBSTITUTE(A11," ","§",2)&"§")-1)) ))>0, IF( COUNT(_xlfn._xlws.FILTER('Bite force'!$I:$I, TRIM(LEFT('Bite force'!$A:$A,SEARCH("§",SUBSTITUTE('Bite force'!$A:$A," ","§",2)&"§")-1))= TRIM(LEFT(A11,SEARCH("§",SUBSTITUTE(A11," ","§",2)&"§")-1)) ))=0, 1, IF( B11=2, AVERAGE(_xlfn._xlws.FILTER('Bite force'!$I:$I, TRIM(LEFT('Bite force'!$A:$A,SEARCH("§",SUBSTITUTE('Bite force'!$A:$A," ","§",2)&"§")-1))= TRIM(LEFT(A11,SEARCH("§",SUBSTITUTE(A11," ","§",2)&"§")-1)) )), MAX(_xlfn._xlws.FILTER('Bite force'!$I:$I, TRIM(LEFT('Bite force'!$A:$A,SEARCH("§",SUBSTITUTE('Bite force'!$A:$A," ","§",2)&"§")-1))= TRIM(LEFT(A11,SEARCH("§",SUBSTITUTE(A11," ","§",2)&"§")-1)) )) ) ), IFERROR( AVERAGE(_xlfn._xlws.FILTER('Bite force'!$I:$I, TRIM(LEFT('Bite force'!$A:$A,SEARCH(" ",'Bite force'!$A:$A&" ")-1))= TRIM(LEFT(A11,SEARCH(" ",A11&" ")-1)) )), 1 ) )} -> 1
A12: ='[1]Base stats'!$B12 -> Camelus dromedarius | B12: =_xlfn.XLOOKUP(A12,'[1]Base stats'!$B:$B,'[1]Base stats'!$O:$O) -> 1 | C12: {=IF( SUMPRODUCT(--( TRIM(LEFT('Bite force'!$A:$A,SEARCH("§",SUBSTITUTE('Bite force'!$A:$A," ","§",2)&"§")-1))= TRIM(LEFT(A12,SEARCH("§",SUBSTITUTE(A12," ","§",2)&"§")-1)) ))>0, IF( COUNT(_xlfn._xlws.FILTER('Bite force'!$I:$I, TRIM(LEFT('Bite force'!$A:$A,SEARCH("§",SUBSTITUTE('Bite force'!$A:$A," ","§",2)&"§")-1))= TRIM(LEFT(A12,SEARCH("§",SUBSTITUTE(A12," ","§",2)&"§")-1)) ))=0, 1, IF( B12=2, AVERAGE(_xlfn._xlws.FILTER('Bite force'!$I:$I, TRIM(LEFT('Bite force'!$A:$A,SEARCH("§",SUBSTITUTE('Bite force'!$A:$A," ","§",2)&"§")-1))= TRIM(LEFT(A12,SEARCH("§",SUBSTITUTE(A12," ","§",2)&"§")-1)) )), MAX(_xlfn._xlws.FILTER('Bite force'!$I:$I, TRIM(LEFT('Bite force'!$A:$A,SEARCH("§",SUBSTITUTE('Bite force'!$A:$A," ","§",2)&"§")-1))= TRIM(LEFT(A12,SEARCH("§",SUBSTITUTE(A12," ","§",2)&"§")-1)) )) ) ), IFERROR( AVERAGE(_xlfn._xlws.FILTER('Bite force'!$I:$I, TRIM(LEFT('Bite force'!$A:$A,SEARCH(" ",'Bite force'!$A:$A&" ")-1))= TRIM(LEFT(A12,SEARCH(" ",A12&" ")-1)) )), 1 ) )} -> 1
A13: ='[1]Base stats'!$B13 -> Lama pacos | B13: =_xlfn.XLOOKUP(A13,'[1]Base stats'!$B:$B,'[1]Base stats'!$O:$O) -> 2 | C13: {=IF( SUMPRODUCT(--( TRIM(LEFT('Bite force'!$A:$A,SEARCH("§",SUBSTITUTE('Bite force'!$A:$A," ","§",2)&"§")-1))= TRIM(LEFT(A13,SEARCH("§",SUBSTITUTE(A13," ","§",2)&"§")-1)) ))>0, IF( COUNT(_xlfn._xlws.FILTER('Bite force'!$I:$I, TRIM(LEFT('Bite force'!$A:$A,SEARCH("§",SUBSTITUTE('Bite force'!$A:$A," ","§",2)&"§")-1))= TRIM(LEFT(A13,SEARCH("§",SUBSTITUTE(A13," ","§",2)&"§")-1)) ))=0, 1, IF( B13=2, AVERAGE(_xlfn._xlws.FILTER('Bite force'!$I:$I, TRIM(LEFT('Bite force'!$A:$A,SEARCH("§",SUBSTITUTE('Bite force'!$A:$A," ","§",2)&"§")-1))= TRIM(LEFT(A13,SEARCH("§",SUBSTITUTE(A13," ","§",2)&"§")-1)) )), MAX(_xlfn._xlws.FILTER('Bite force'!$I:$I, TRIM(LEFT('Bite force'!$A:$A,SEARCH("§",SUBSTITUTE('Bite force'!$A:$A," ","§",2)&"§")-1))= TRIM(LEFT(A13,SEARCH("§",SUBSTITUTE(A13," ","§",2)&"§")-1)) )) ) ), IFERROR( AVERAGE(_xlfn._xlws.FILTER('Bite force'!$I:$I, TRIM(LEFT('Bite force'!$A:$A,SEARCH(" ",'Bite force'!$A:$A&" ")-1))= TRIM(LEFT(A13,SEARCH(" ",A13&" ")-1)) )), 1 ) )} -> 1
... A361: ='[1]Base stats'!$B361 -> Pteranodon longiceps | B361: =_xlfn.XLOOKUP(A361,'[1]Base stats'!$B:$B,'[1]Base stats'!$O:$O) -> 0 | C361: {=IF( SUMPRODUCT(--( TRIM(LEFT('Bite force'!$A:$A,SEARCH("§",SUBSTITUTE('Bite force'!$A:$A," ","§",2)&"§")-1))= TRIM(LEFT(A361,SEARCH("§",SUBSTITUTE(A361," ","§",2)&"§")-1)) ))>0, IF( COUNT(_xlfn._xlws.FILTER('Bite force'!$I:$I, TRIM(LEFT('Bite force'!$A:$A,SEARCH("§",SUBSTITUTE('Bite force'!$A:$A," ","§",2)&"§")-1))= TRIM(LEFT(A361,SEARCH("§",SUBSTITUTE(A361," ","§",2)&"§")-1)) ))=0, 1, IF( B361=2, AVERAGE(_xlfn._xlws.FILTER('Bite force'!$I:$I, TRIM(LEFT('Bite force'!$A:$A,SEARCH("§",SUBSTITUTE('Bite force'!$A:$A," ","§",2)&"§")-1))= TRIM(LEFT(A361,SEARCH("§",SUBSTITUTE(A361," ","§",2)&"§")-1)) )), MAX(_xlfn._xlws.FILTER('Bite force'!$I:$I, TRIM(LEFT('Bite force'!$A:$A,SEARCH("§",SUBSTITUTE('Bite force'!$A:$A," ","§",2)&"§")-1))= TRIM(LEFT(A361,SEARCH("§",SUBSTITUTE(A361," ","§",2)&"§")-1)) )) ) ), IFERROR( AVERAGE(_xlfn._xlws.FILTER('Bite force'!$I:$I, TRIM(LEFT('Bite force'!$A:$A,SEARCH(" ",'Bite force'!$A:$A&" ")-1))= TRIM(LEFT(A361,SEARCH(" ",A361&" ")-1)) )), 1 ) )} -> 1

Sheet Teeth
A1: dataset from Christiansen & Adolfssen (2005) https://doi.org/10.1017/S0952836905006643 and Plavcan & Ruff (2008) https://doi.org/10.1002/ajpa.20779
A2: Species | B2: ln body mass (kg) | C2: ln maximum canine length (cm) | D2: Canine length factor
A3: Alopex lagopus | B3: 1.1600209 | C3: 0.32280787 | D3: =EXP(C3)/EXP(0.358*B3-0.222) -> 1.1382823
A4: Canis latrans | B4: 2.3504224 | C4: 0.75141609 | D4: =EXP(C4)/EXP(0.358*B4-0.222) -> 1.1410682
A5: Canis familiaris | B5: 3.6360549 | C5: 1.0321875 | D5: =EXP(C5)/EXP(0.358*B5-0.222) -> 0.95359131
A6: Canis lupus | B6: 3.6360549 | C6: 1.1600209 | D6: =EXP(C6)/EXP(0.358*B6-0.222) -> 1.0836265
A7: Canis lupus | B7: 3.4998354 | C7: 1.062294 | D7: =EXP(C7)/EXP(0.358*B7-0.222) -> 1.0318497
A8: Canis mesomelas | B8: 2.0399208 | C8: 0.48980626 | D8: =EXP(C8)/EXP(0.358*B8-0.222) -> 0.98168442
A9: Cerdocyon thous | B9: 1.8049073 | C9: 0.26236426 | D9: =EXP(C9)/EXP(0.358*B9-0.222) -> 0.85061764
A10: Chrysocyon brachyurus | B10: 3.4406501 | C10: 1.0681531 | D10: =EXP(C10)/EXP(0.358*B10-0.222) -> 1.0601393
A11: Cuon alpinus | B11: 2.4857994 | C11: 0.69314718 | D11: =EXP(C11)/EXP(0.358*B11-0.222) -> 1.025552
A12: Dusicyon gymnocerus | B12: 1.8327089 | C12: 0.53649337 | D12: =EXP(C12)/EXP(0.358*B12-0.222) -> 1.1078083
A13: Fennecus zerda | B13: 0.64829908 | C13: -0.11653382 | D13: =EXP(C13)/EXP(0.358*B13-0.222) -> 0.88106411
A14: Lycalopex vetulus | B14: 1.3355662 | C14: 0.30010459 | D14: =EXP(C14)/EXP(0.358*B14-0.222) -> 1.044953
... A221: Varecia variegate | B221: 1.2739652 | C221: 0.26849925 | D221: =EXP(C221)/EXP(0.358*B221-0.222) -> 1.0350189

Sheet Sharpness
A1: Claws sharpness
A2: Species | B2: Mass (kg) | C2: Claw sharpness (px) | D2: ln mass (kg) | E2: ln claw sharpness (mm^2)
A3: Panthera tigris | B3: 162.564 | C3: 8.06 | D3: =LN(B3) -> 5.0910718 | E3: =LN(PI()*((C3*100/170)/2)^2) -> 2.8710061
A4: Panthera leo | B4: 161.4991 | C4: 8.6 | D4: =LN(B4) -> 5.0844996 | E4: =LN(PI()*((C4*100/170)/2)^2) -> 3.0007034
A5: Puma concolor | B5: 51.6 | C5: 5.66 | D5: =LN(B5) -> 3.9435217 | E5: =LN(PI()*((C5*100/170)/2)^2) -> 2.1640268
A6: Panthera onca | B6: 100 | C6: 4.47 | D6: =LN(B6) -> 4.6051702 | E6: =LN(PI()*((C6*100/170)/2)^2) -> 1.6919558
A7: Acinonyx jubatus | B7: 50 | C7: 6.4 | D7: =LN(B7) -> 3.912023 | E7: =LN(PI()*((C7*100/170)/2)^2) -> 2.409775
A8: Panthera pardus | B8: 54.9997 | C8: 5.1 | D8: =LN(B8) -> 4.0073277 | E8: =LN(PI()*((C8*100/170)/2)^2) -> 1.9556601
A9: Lynx lynx | B9: 17.95 | C9: 5.1 | D9: =LN(B9) -> 2.8875901 | E9: =LN(PI()*((C9*100/170)/2)^2) -> 1.9556601
A10: Lynx canadensis | B10: 9.3732 | C10: 5 | D10: =LN(B10) -> 2.2378546 | E10: =LN(PI()*((C10*100/170)/2)^2) -> 1.9160548
A11: Lynx rufus | B11: 8.9041 | C11: 3.61 | D11: =LN(B11) -> 2.1865118 | E11: =LN(PI()*((C11*100/170)/2)^2) -> 1.2645946
A12: Ursus arctos | B12: 206 | C12: 7.62 | D12: =LN(B12) -> 5.3278762 | E12: =LN(PI()*((C12*100/170)/2)^2) -> 2.7587318
A13: Ursus maritimus | B13: 425 | C13: 6.4 | D13: =LN(B13) -> 6.0520892 | E13: =LN(PI()*((C13*100/170)/2)^2) -> 2.409775
A14: Melursus ursinus | B14: 86.26 | C14: 10 | D14: =LN(B14) -> 4.457366 | E14: =LN(PI()*((C14*100/170)/2)^2) -> 3.3023492
... A19: Erethizon dorsatum | B19: 7.0853 | C19: 4.47 | D19: =LN(B19) -> 1.9580222 | E19: =LN(PI()*((C19*100/170)/2)^2) -> 1.6919558
A21: Teeth sharpness
A22: Species | B22: Body mass (kg) | C22: Bite pressure (MPa) | D22: Source | E22: Bite force (N) | F22: Contact area (mm^2) | G22: ln body mass (kg) | H22: ln contact area (mm^2)
A23: Dunkleosteus terrelli | B23: 1008.4 | C23: =(30/20*107) -> 160.5 | D23: Corrected Fuerst et al. (2008) http://dx.doi.org/10.1098/rsbl.2006.0569 | E23: =30/20*4414 -> 6621 | F23: =E23/C23 -> 41.252336 | G23: =LN(B23) -> 6.9161202 | H23: =LN(F23) -> 3.7197078
A24: Crocodylus acutus | B24: 132 | C24: 410 | D24: Erickson et al. (2012) https://doi.org/10.1371/journal.pone.0031781 | E24: 2599 | F24: =E24/C24 -> 6.3390244 | G24: =LN(B24) -> 4.8828019 | H24: =LN(F24) -> 1.8467249
A25: Crocodylus intermedius | B25: 182 | C25: 1344 | D25: Erickson et al. (2012) https://doi.org/10.1371/journal.pone.0031781 | E25: 4283 | F25: =E25/C25 -> 3.186756 | G25: =LN(B25) -> 5.2040067 | H25: =LN(F25) -> 1.1590035
A26: Crocodylus johnsoni | B26: 20 | C26: 624 | D26: Erickson et al. (2012) https://doi.org/10.1371/journal.pone.0031781 | E26: 629 | F26: =E26/C26 -> 1.0080128 | G26: =LN(B26) -> 2.9957323 | H26: =LN(F26) -> 0.0079808883
A27: Crocodylus moreletii | B27: 110 | C27: 195 | D27: Erickson et al. (2012) https://doi.org/10.1371/journal.pone.0031780 | E27: 3069 | F27: =E27/C27 -> 15.738462 | G27: =LN(B27) -> 4.7004804 | H27: =LN(F27) -> 2.7561075
A28: Crocodylus niloticus | B28: 86 | C28: 451 | D28: Erickson et al. (2012) https://doi.org/10.1371/journal.pone.0031781 | E28: 2007 | F28: =E28/C28 -> 4.4501109 | G28: =LN(B28) -> 4.4543473 | H28: =LN(F28) -> 1.492929
A29: Crocodylus novaeguineae | B29: 154 | C29: 439 | D29: Erickson et al. (2012) https://doi.org/10.1371/journal.pone.0031781 | E29: 3928 | F29: =E29/C29 -> 8.9476082 | G29: =LN(B29) -> 5.0369526 | H29: =LN(F29) -> 2.1913863
A30: Crocodylus palustris | B30: 207 | C30: 382 | D30: Erickson et al. (2012) https://doi.org/10.1371/journal.pone.0031781 | E30: 4194 | F30: =E30/C30 -> 10.979058 | G30: =LN(B30) -> 5.3327188 | H30: =LN(F30) -> 2.3959896
A31: Crocodylus porosus | B31: 272 | C31: 679 | D31: Erickson et al. (2012) https://doi.org/10.1371/journal.pone.0031781 | E31: 6792 | F31: =E31/C31 -> 10.002946 | G31: =LN(B31) -> 5.6058021 | H31: =LN(F31) -> 2.3028796
A32: Crocodylus rhombifer | B32: 52 | C32: 312 | D32: Erickson et al. (2012) https://doi.org/10.1371/journal.pone.0031781 | E32: 1379 | F32: =E32/C32 -> 4.4198718 | G32: =LN(B32) -> 3.9512437 | H32: =LN(F32) -> 1.4861107
A33: Crocodylus siamensis | B33: 69 | C33: 513 | D33: Erickson et al. (2012) https://doi.org/10.1371/journal.pone.0031781 | E33: 2227 | F33: =E33/C33 -> 4.3411306 | G33: =LN(B33) -> 4.2341065 | H33: =LN(F33) -> 1.4681348
A34: Ostoelaemus tetraspis | B34: 17 | C34: 400 | D34: Erickson et al. (2012) https://doi.org/10.1371/journal.pone.0031781 | E34: 1164 | F34: =E34/C34 -> 2.91 | G34: =LN(B34) -> 2.8332133 | H34: =LN(F34) -> 1.0681531
A35: Gavialis gangeticus | B35: 112 | C35: 1154 | D35: Erickson et al. (2012) https://doi.org/10.1371/journal.pone.0031781 | E35: 924 | F35: =E35/C35 -> 0.80069324 | G35: =LN(B35) -> 4.7184989 | H35: =LN(F35) -> -0.22227738
... A45: Tyrannosaurus rex | B45: 7206.7 | C45: 4165.5116 | D45: Corrected Gignac et al. (2017) https://doi.org/10.1038/s41598-017-02161-w | E45: 46028.922 | F45: =E45/C45 -> 11.050005 | G45: =LN(B45) -> 8.8827664 | H45: =LN(F45) -> 2.4024308
A46: Panthera tigris | B46: 200 | C46: =E46/F46 -> 654.51395 | D46: Hartstone-Rose et al. (2012) https://doi.org/10.1002/ar.22518 | E46: 7037.4 | F46: =PI()*(3.7/2)^2 -> 10.752101 | G46: =LN(B46) -> 5.2983174 | H46: =LN(F46) -> 2.3751012
A47: Panthera onca | B47: 100 | C47: =E47/F47 -> 970.74178 | D47: Hartstone-Rose et al. (2012) https://doi.org/10.1002/ar.22518 | E47: 5035.7 | F47: =PI()*(2.57/2)^2 -> 5.1874763 | G47: =LN(B47) -> 4.6051702 | H47: =LN(F47) -> 1.6462473
A48: Caracal caracal | B48: 16.59 | C48: =E48/F48 -> 591.20862 | D48: Hartstone-Rose et al. (2012) https://doi.org/10.1002/ar.22518 | E48: 778.7 | F48: =PI()*(1.85*0.7/2)^2 -> 1.3171324 | G48: =LN(B48) -> 2.8088001 | H48: =LN(F48) -> 0.27545692
A49: Leptailurus serval | B49: 13.9 | C49: =E49/F49 -> 528.00738 | D49: Hartstone-Rose et al. (2012) https://doi.org/10.1002/ar.22518 | E49: 680.5 | F49: =PI()*(1.83*0.7/2)^2 -> 1.2888078 | G49: =LN(B49) -> 2.6318888 | H49: =LN(F49) -> 0.25371757
A50: Leopardus pardalis | B50: 11.59 | C50: =E50/F50 -> 404.97803 | D50: Hartstone-Rose et al. (2012) https://doi.org/10.1002/ar.22518 | E50: 733.9 | F50: =PI()*(2.17*0.7/2)^2 -> 1.8121971 | G50: =LN(B50) -> 2.4501427 | H50: =LN(F50) -> 0.59453997
A51: Lynx rufus | B51: 15.5 | C51: =E51/F51 -> 437.04836 | D51: Hartstone-Rose et al. (2012) https://doi.org/10.1002/ar.22518 | E51: 515.1 | F51: =PI()*(1.75*0.7/2)^2 -> 1.1785881 | G51: =LN(B51) -> 2.74084 | H51: =LN(F51) -> 0.16431721
A52: Neofelis nebulosa | B52: 24 | C52: =E52/F52 -> 729.47233 | D52: Hartstone-Rose et al. (2012) https://doi.org/10.1002/ar.22518 | E52: 1089.5 | F52: =PI()*(1.97*0.7/2)^2 -> 1.4935453 | G52: =LN(B52) -> 3.1780538 | H52: =LN(F52) -> 0.40115272
A53: Panthera pardus | B53: 34.1 | C53: =E53/F53 -> 1131.0963 | D53: Hartstone-Rose et al. (2012) https://doi.org/10.1002/ar.22518 | E53: 1662.5 | F53: =PI()*(2.28*0.6/2)^2 -> 1.469813 | G53: =LN(B53) -> 3.5292974 | H53: =LN(F53) -> 0.38513516
A54: Panthera uncia | B54: 38.64 | C54: =E54/F54 -> 845.34992 | D54: Hartstone-Rose et al. (2012) https://doi.org/10.1002/ar.22518 | E54: 1485.9 | F54: =PI()*(1.87*0.8/2)^2 -> 1.7577337 | G54: =LN(B54) -> 3.654288 | H54: =LN(F54) -> 0.56402528

Sheet Limb force
A1: limb force
A2: Species | B2: Body mass (kg) | C2: Limb-produced force (N) | D2: Source | E2: ln body mass (kg) | F2: ln limb-produced force (N)
A3: Equus caballus (kicking) | B3: 660 | C3: 8722 | D3: Wachenfelt et al. (2013) https://doi.org/10.1016/j.biosystemseng.2013.10.013 | E3: =LN(B3) -> 6.4922398 | F3: =LN(C3) -> 9.0736038
A4: Equus caballus (kicking, supporting leg) | B4: 670 | C4: 7805 | D4: https://www.zora.uzh.ch/id/eprint/125608/1/03_Fuerst_SAT_2016.pdf | E4: =LN(B4) -> 6.5072777 | F4: =LN(C4) -> 8.9625198
A5: Equus caballus (kicking) | B5: =1000/1.8 -> 555.55556 | C5: 10000 | D5: Kriss & Kriss (1997) https://doi.org/10.1097/00005373-199707000-00022 | E5: =LN(B5) -> 6.3199686 | F5: =LN(C5) -> 9.2103404
A6: Homo sapiens (kicking) | B6: 82.9 | C6: 6310 | D6: https://www.mdpi.com/2075-4663/12/8/205 | E6: =LN(B6) -> 4.4176351 | F6: =LN(C6) -> 8.749891
A7: Sagittarius serpentarius (kicking) | B7: 3.96 | C7: 195 | D7: Portugal et al. (2015) https://doi.org/10.1016/j.cub.2015.12.004 | E7: =LN(B7) -> 1.376244 | F7: =LN(C7) -> 5.2729996
A8: Homo sapiens (punching) | B8: =AVERAGE(65,80) -> 72.5 | C8: 2120 | D8: https://www.mediasphera.ru/issues/sudebno-meditsinskaya-ekspertiza/2014/3/downloads/ru/030039-4521201432 | E8: =LN(B8) -> 4.2835866 | F8: =LN(C8) -> 7.6591714
A9: Homo sapiens (punching) | B9: 82.9 | C9: 2501 | D9: https://www.mdpi.com/2075-4663/12/8/205 | E9: =LN(B9) -> 4.4176351 | F9: =LN(C9) -> 7.8244459
A10: Bubo virginianus (grip) | B10: 1.3973 | C10: 130.4 | D10: Ward et al. (2002) https://doi.org/10.1093/auk/119.4.1052 | E10: =LN(B10) -> 0.3345418 | F10: =LN(C10) -> 4.8706066
A11: Bubo virginianus (grip) | B11: 1.6 | C11: 277.7 | D11: Ward et al. (2002) https://doi.org/10.1093/auk/119.4.1052 | E11: =LN(B11) -> 0.47000363 | F11: =LN(C11) -> 5.6265414
A12: Otus asio (grip) | B12: 0.1508 | C12: 18.94 | D12: Ward et al. (2002) https://doi.org/10.1093/auk/119.4.1052 | E12: =LN(B12) -> -1.8918008 | F12: =LN(C12) -> 2.9412761
A13: Strix varia (grip) | B13: 0.7833 | C13: 45.32 | D13: Ward et al. (2002) https://doi.org/10.1093/auk/119.4.1052 | E13: =LN(B13) -> -0.24423951 | F13: =LN(C13) -> 3.8137484
A14: Falco sparverius (grip) | B14: 0.1221 | C14: 7.73 | D14: Ward et al. (2002) https://doi.org/10.1093/auk/119.4.1052 | E14: =LN(B14) -> -2.1029149 | F14: =LN(C14) -> 2.0451089
A15: Buteo lineatus (grip) | B15: 0.624 | C15: 34.42 | D15: Ward et al. (2002) https://doi.org/10.1093/auk/119.4.1052 | E15: =LN(B15) -> -0.47160491 | F15: =LN(C15) -> 3.5386378
A16: Buteo jamaicensis (grip) | B16: 1.3576 | C16: 72.32 | D16: Ward et al. (2002) https://doi.org/10.1093/auk/119.4.1052 | E16: =LN(B16) -> 0.30571843 | F16: =LN(C16) -> 4.2811007
A17: Sus scrofa (ramming) | B17: 90 | C17: 2144 | D17: Wachenfelt et al. (2013) https://doi.org/10.1016/j.biosystemseng.2013.10.013 | E17: =LN(B17) -> 4.4998097 | F17: =LN(C17) -> 7.6704285
A18: Ovis canadensis (ramming) | B18: 100 | C18: 3400 | D18: https://www.sciencedirect.com/science/article/abs/pii/S1742706123007122#:~:text=A%20100%20kg%20bighorn%20sheep,combat%20%5B1%2C2%5D. | E18: =LN(B18) -> 4.6051702 | F18: =LN(C18) -> 8.1315307
A19: Elephas maximus (running) | B19: 1740 | C19: 23000 | D19: Genin et al. (2010) http://dx.doi.org/10.1242/jeb.035436 | E19: =LN(B19) -> 7.4616404 | F19: =LN(C19) -> 10.043249
A20: Lepus sp. (running) | B20: 2.4 | C20: =4.3*B20*9.80665 -> 101.20463 | D20: Alexander (1985) https://doi.org/10.1242/jeb.115.1.231 | E20: =LN(B20) -> 0.87546874 | F20: =LN(C20) -> 4.6171445
A21: Elephas maximus (running) | B21: 2500 | C21: =1*B21*9.80665 -> 24516.625 | D21: Alexander (1985) https://doi.org/10.1242/jeb.115.1.231 | E21: =LN(B21) -> 7.824046 | F21: =LN(C21) -> 10.107107
A22: Varanus komodoensis (pulling) | B22: 25.45 | C22: 243.77 | D22: D'Amore et al. (2011) https://doi.org/10.1371/journal.pone.0026226 | E22: =LN(B22) -> 3.2367157 | F22: =LN(C22) -> 5.4962252
A23: Pan sp. (pulling) | B23: 67.9 | C23: 5607 | D23: O’Neill et al. (2017) https://doi.org/10.1073/pnas.1619071114 | E23: =LN(B23) -> 4.218036 | F23: =LN(C23) -> 8.6317711
A24: Pan sp. (pulling) | B24: 47.6 | C24: 2167 | D24: O’Neill et al. (2017) https://doi.org/10.1073/pnas.1619071114 | E24: =LN(B24) -> 3.8628328 | F24: =LN(C24) -> 7.681099
A25: Pan sp. (pulling) | B25: 27.9 | C25: 1157 | D25: O’Neill et al. (2017) https://doi.org/10.1073/pnas.1619071114 | E25: =LN(B25) -> 3.3286267 | F25: =LN(C25) -> 7.0535857
A26: Pan sp. (pulling) | B26: 42.8 | C26: 1570 | D26: O’Neill et al. (2017) https://doi.org/10.1073/pnas.1619071114 | E26: =LN(B26) -> 3.7565381 | F26: =LN(C26) -> 7.3588309
A27: Homo sapiens (pulling) | B27: 67.4 | C27: 2185 | D27: O’Neill et al. (2017) https://doi.org/10.1073/pnas.1619071114 | E27: =LN(B27) -> 4.210645 | F27: =LN(C27) -> 7.6893711
A28: Homo sapiens (pulling) | B28: 69.7 | C28: 2336 | D28: O’Neill et al. (2017) https://doi.org/10.1073/pnas.1619071114 | E28: =LN(B28) -> 4.2442003 | F28: =LN(C28) -> 7.7561953
A29: Homo sapiens (pulling) | B29: 81.8 | C29: 890 | D29: O’Neill et al. (2017) https://doi.org/10.1073/pnas.1619071114 | E29: =LN(B29) -> 4.4042772 | F29: =LN(C29) -> 6.7912215
A30: Homo sapiens (pulling) | B30: 64.6 | C30: 1567 | D30: O’Neill et al. (2017) https://doi.org/10.1073/pnas.1619071114 | E30: =LN(B30) -> 4.1682144 | F30: =LN(C30) -> 7.3569182
A31: Canis familiaris (pulling) | B31: 39 | C31: =B31*0.38*9.80665 -> 145.33455 | D31: https://physoc.onlinelibrary.wiley.com/doi/10.1113/jphysiol.1957.sp005807 | E31: =LN(B31) -> 3.6635616 | F31: =LN(C31) -> 4.9790383
A32: Equus caballus (trailing) | B32: =C32/13 -> 640 | C32: 8320 | D32: Wachenfelt et al. (2013) https://doi.org/10.1016/j.biosystemseng.2013.10.013 | E32: =LN(B32) -> 6.4614682 | F32: =LN(C32) -> 9.0264175
A33: Canis familiaris (jumping) | B33: 22.29 | C33: =34.12*22.29 -> 760.5348 | D33: https://www.doganddrive.com/wp-content/uploads/2023/04/VeterinaryRecord-2018-Pardey-Peakforelimbgroundreactionforcesexperiencedbydogsjumpingfromasimulatedcar.pdf | E33: =LN(B33) -> 3.1041381 | F33: =LN(C33) -> 6.6340219
A34: Rana pipiens (jumping) | B34: 0.0553 | C34: =B34*2.42*9.80665 -> 1.3123847 | D34: Astley & Roberts (2014) http://dx.doi.org/10.1242/jeb.110296 | E34: =LN(B34) -> -2.8949824 | F34: =LN(C34) -> 0.2718459
A35: Homo sapiens (jumping) | B35: 61.5 | C35: =2.3*B35*9.80665 -> 1387.1506 | D35: Scholz et al. (2006) https://doi.org/10.1098%2Frspb.2006.3568 | E35: =LN(B35) -> 4.1190372 | F35: =LN(C35) -> 7.235007
A36: Homo sapiens (jumping) | B36: 82.9 | C36: 4531 | D36: https://www.mdpi.com/2075-4663/12/8/205 | E36: =LN(B36) -> 4.4176351 | F36: =LN(C36) -> 8.4186979
A37: Pan paniscus (jumping) | B37: 34 | C37: =2.6*B37*9.80665 -> 866.90786 | D37: Scholz et al. (2006) https://doi.org/10.1098%2Frspb.2006.3568 | E37: =LN(B37) -> 3.5263605 | F37: =LN(C37) -> 6.7649327
A38: Gallago sp. (jumping) | B38: 0.25 | C38: =18*B38*9.80665 -> 44.129925 | D38: Alexander (1985) https://doi.org/10.1242/jeb.115.1.231 | E38: =LN(B38) -> -1.3862944 | F38: =LN(C38) -> 3.7871381
A39: Canis familiaris (jumping) | B39: 40.8 | C39: 2043.8 | D39: Yanoff et al. (1992) https://www.thieme-connect.com/products/ejournals/abstract/10.1055/s-0038-1633066 | E39: =LN(B39) -> 3.7086821 | F39: =LN(C39) -> 7.6225661
A40: Canis familiaris (jumping) | B40: 28.1 | C40: 1480.8 | D40: Yanoff et al. (1992) https://www.thieme-connect.com/products/ejournals/abstract/10.1055/s-0038-1633066 | E40: =LN(B40) -> 3.3357696 | F40: =LN(C40) -> 7.3003378
...

Sheet Force-energy
A1: Force-enegy ratio
A2: Species | B2: Actual Mass (kg) | C2: Kinetic impact energy Eₖ (J) | D2: Force (N) | E2: V (m/s) | F2: M (kg) | G2: Source | H2: ln Kinetic impact energy Eₖ (J) | I2: ln Force (N)
A3: Test | B3: =F3 -> 6.5 | C3: 32 | D3: 3998 | E3: 3.1 | F3: 6.5 | G3: https://www.sciencedirect.com/science/article/abs/pii/S1537511020301008 | H3: =LN(C3) -> 3.4657359 | I3: =LN(D3) -> 8.2935495
A4: Test | B4: =F4 -> 6.5 | C4: 64 | D4: 5823 | E4: 4.4 | F4: 6.5 | G4: https://www.sciencedirect.com/science/article/abs/pii/S1537511020301008 | H4: =LN(C4) -> 4.1588831 | I4: =LN(D4) -> 8.6695709
A5: Test | B5: =F5 -> 6.5 | C5: 96 | D5: 7312 | E5: 5.4 | F5: 6.5 | G5: https://www.sciencedirect.com/science/article/abs/pii/S1537511020301008 | H5: =LN(C5) -> 4.5643482 | I5: =LN(D5) -> 8.8972721
A6: Test | B6: =F6 -> 6.5 | C6: 128 | D6: 8794 | E6: 6.3 | F6: 6.5 | G6: https://www.sciencedirect.com/science/article/abs/pii/S1537511020301008 | H6: =LN(C6) -> 4.8520303 | I6: =LN(D6) -> 9.0818249
A7: Test | B7: =F7 -> 16.5 | C7: 81 | D7: 7456 | E7: 3.1 | F7: 16.5 | G7: https://www.sciencedirect.com/science/article/abs/pii/S1537511020301008 | H7: =LN(C7) -> 4.3944492 | I7: =LN(D7) -> 8.9167744
A8: Test | B8: =F8 -> 16.5 | C8: 162 | D8: 11068 | E8: 4.4 | F8: 16.5 | G8: https://www.sciencedirect.com/science/article/abs/pii/S1537511020301008 | H8: =LN(C8) -> 5.0875963 | I8: =LN(D8) -> 9.3118133
A9: Test | B9: =F9 -> 16.5 | C9: 243 | D9: 13935 | E9: 5.4 | F9: 16.5 | G9: https://www.sciencedirect.com/science/article/abs/pii/S1537511020301008 | H9: =LN(C9) -> 5.4930614 | I9: =LN(D9) -> 9.5421589
A10: Test | B10: =F10 -> 16.5 | C10: 324 | D10: 16220 | E10: 6.3 | F10: 16.5 | G10: https://www.sciencedirect.com/science/article/abs/pii/S1537511020301008 | H10: =LN(C10) -> 5.7807435 | I10: =LN(D10) -> 9.6940003
A11: Test | B11: =F11 -> 26.5 | C11: 130 | D11: 8885 | E11: 3.1 | F11: 26.5 | G11: https://www.sciencedirect.com/science/article/abs/pii/S1537511020301008 | H11: =LN(C11) -> 4.8675345 | I11: =LN(D11) -> 9.0921197
A12: Test | B12: =F12 -> 26.5 | C12: 260 | D12: 13853 | E12: 4.4 | F12: 26.5 | G12: https://www.sciencedirect.com/science/article/abs/pii/S1537511020301008 | H12: =LN(C12) -> 5.5606816 | I12: =LN(D12) -> 9.5362571
A13: Test | B13: =F13 -> 26.5 | C13: 390 | D13: 16625 | E13: 5.4 | F13: 26.5 | G13: https://www.sciencedirect.com/science/article/abs/pii/S1537511020301008 | H13: =LN(C13) -> 5.9661467 | I13: =LN(D13) -> 9.7186629
A14: Test | B14: =F14 -> 26.5 | C14: 520 | D14: 18548 | E14: 6.3 | F14: 26.5 | G14: https://www.sciencedirect.com/science/article/abs/pii/S1537511020301008 | H14: =LN(C14) -> 6.2538288 | I14: =LN(D14) -> 9.8281172
... A18: Test | B18: =F18 -> 36.5 | C18: 716 | D18: 21459 | E18: 6.3 | F18: 36.5 | G18: https://www.sciencedirect.com/science/article/abs/pii/S1537511020301008 | H18: =LN(C18) -> 6.5736802 | I18: =LN(D18) -> 9.9738994
A19: Homo sapiens | B19: 82.9 | C19: =1/2*F19*E19^2 -> 27.962193 | D19: 2501 | E19: =17.2/F19 -> 3.2514178 | F19: 5.29 | G19: https://www.mdpi.com/2075-4663/12/8/205 | H19: =LN(C19) -> 3.3308533 | I19: =LN(D19) -> 7.8244459
A20: Homo sapiens | B20: 82.9 | C20: =1/2*F20*E20^2 -> 20.983932 | D20: 4210 | E20: =(14.9/F20) -> 2.8166352 | F20: 5.29 | G20: https://www.mdpi.com/2075-4663/12/8/205 | H20: =LN(C20) -> 3.043757 | I20: =LN(D20) -> 8.3452179
A21: Homo sapiens | B21: 82.9 | C21: =1/2*F21*E21^2 -> 29.277883 | D21: 4677 | E21: =(17.6/F21) -> 3.3270321 | F21: 5.29 | G21: https://www.mdpi.com/2075-4663/12/8/205 | H21: =LN(C21) -> 3.3768324 | I21: =LN(D21) -> 8.4504122
A22: Homo sapiens | B22: 82.9 | C22: =1/2*F22*E22^2 -> 845.36738 | D22: 6310 | E22: =(154.4/F22) -> 10.950355 | F22: 14.1 | G22: https://www.mdpi.com/2075-4663/12/8/205 | H22: =LN(C22) -> 6.7397713 | I22: =LN(D22) -> 8.749891
A23: Sagittarius serpentarius | B23: 3.96 | C23: =1/2*3.96*E23^2 -> 1.0802557 | D23: 195 | E23: =D23*0.015/F23 -> 0.73863636 | F23: 3.96 | G23: Portugal et al. (2015) https://doi.org/10.1016/j.cub.2015.12.004 | H23: =LN(C23) -> 0.077197756 | I23: =LN(D23) -> 5.2729996
A24: Homo sapiens | B24: =AVERAGE(65,80) -> 72.5 | C24: 560.9 | D24: 2120 | E24: 5.2 | F24: =2*C24/E24^2 -> 41.486686 | G24: https://www.mediasphera.ru/issues/sudebno-meditsinskaya-ekspertiza/2014/3/downloads/ru/030039-4521201432 | H24: =LN(C24) -> 6.3295426 | I24: =LN(D24) -> 7.6591714
A25: Homo sapiens | B25: 64.1 | C25: 2299 | D25: 3284 | E25: 7.2 | F25: =2*C25/E25^2 -> 88.695988 | G25: http://proceedings.archbudo.com/wp-content/uploads/2015/09/158_ArchBudoConfProc.pdf | H25: =LN(C25) -> 7.7402295 | I25: =LN(D25) -> 8.0968175

Sheet Speed
A1: Running speed
A2: Species | B2: Body mass (kg) | C2: Body length (m) | D2: Maximum relative running speed (body lengths/s) | E2: Speed (km/h) | F2: ln body mass (kg) | G2: ln speed (km/h)
A3: Loxodonta africana | B3: 6000 | C3: 6.75 | D3: 1.4 | E3: =C3*D3*3.6 -> 34.02 | F3: =LN(B3) -> 8.6995147 | G3: =LN(E3) -> 3.5269486
A4: Elephas maximus | B4: 4000 | C4: 5.95 | D4: 1.18 | E4: =C4*D4*3.6 -> 25.2756 | F4: =LN(B4) -> 8.2940496 | G4: =LN(E4) -> 3.2298395
A5: Ceratotherium simum | B5: 2000 | C5: 3.78 | D5: 1.79 | E5: =C5*D5*3.6 -> 24.35832 | F5: =LN(B5) -> 7.6009025 | G5: =LN(E5) -> 3.1928735
A6: Diceros bicornis | B6: 1200 | C6: 3.38 | D6: 3.6 | E6: =C6*D6*3.6 -> 43.8048 | F6: =LN(B6) -> 7.0900768 | G6: =LN(E6) -> 3.7797434
A7: Equus caballus | B7: 350 | C7: 2.5 | D7: 7.56 | E7: =C7*D7*3.6 -> 68.04 | F7: =LN(B7) -> 5.8579332 | G7: =LN(E7) -> 4.2200958
A8: Equus zebra | B8: 300 | C8: 2.35 | D8: 7.35 | E8: =C8*D8*3.6 -> 62.181 | F8: =LN(B8) -> 5.7037825 | G8: =LN(E8) -> 4.1300495
A9: Tapirus bairdii | B9: 250 | C9: 2.08 | D9: 5.18 | E9: =C9*D9*3.6 -> 38.78784 | F9: =LN(B9) -> 5.5214609 | G9: =LN(E9) -> 3.6581068
